Workbook

Sheet KPIKudo
B1: 2022 | F1: 2023 | AE1: 2024
B2: 31 Ekim-11 Kasım | C2: 14-25 Kasım | D2: 28 Kasım-9 Aralık | E2: 12-23 aralık | F2: 26 aralık-6 ocak | G2: 9 ocak-20 ocak 2023 | H2: 23 ocak-3 şubat 2023 | I2: 6 şubat-17 şubat 2023 | J2: 20 şubat-5 mart 2023 | K2: 6 mart-19 mart 2023 | L2: 20 mart-2 nisan 2023 | M2: 3-16 nisan 2023 | N2: 17 Nisan-1 Mayıs 2023 | O2: 2 mayıs-14 mayıs 2023 | P2: 15 Mayıs-28 Mayıs | Q2: 29 mayıs-11 Haziran 2023 | R2: 12-25 Haziran 2023 | S2: 26 Haziran-16 Temmuz | T2: 17-30 Temmuz 2023 | U2: 31 Temmuz-13 Ağustos 2023 | V2: 14-27 Ağustos 2023 | W2: 28 Ağustos-17 Eylül 2023 | X2: 18 Eylül-1 Ekim 2023 | Y2: 2-15 Ekim 2023 | Z2: 16-29 Ekim 2023 | AA2: 30 Ekim- 12 Kasım | AB2: 13-26 Kasım | AC2: 27 kasım-10 Aralık | AD2: 11 Aralık-24Aralık 2023 | AE2: 25 Aralık-7 ocak 2024 | AF2: 8 Ocak-21 Ocak 2024 | AG2: 22 Ocak-4 Şubat 2024 | AH2: 5-18 Şubat 2024 | AI2: 19 şubat-3 Mart 2024 | AJ2: 4-17 Mart 2024 | AK2: 18-31 Mart 2024 | AL2: 1-21 Nisan 2024 | AM2: 22 Nisan-5 Mayıs 2024 | AN2: 6-19 Mayıs 2024 | AO2: 20 Mayıs-2 Haziran 2024 | AP2: 3-16 Haziran 2024 | AQ2: 17 Haziran-7 temmuz 2024 | AR2: 8-21 Temmuz 2024 | AS2: 22 Temmuz-4 Ağustos 2024 | AT2: 5-18 Ağustos 2024 | AU2: 19-30 Ağustos 2024 | AV2: 2-29 Eylül 2024 | AW2: 30 Eylül-13 Ekim | AX2: 14-29 Ekim | AY2: 30 Ekim-10 Kasım | AZ2: 11-24 Kasım | BA2: 25 Kasım-8 Aralık 2024 | BB2: 9-22 Aralık 2024 | BC2: 23 Aralık-8 ocak 2025 | BD2: 9-22 Ocak 2025 | BE2: 23 OCAK-5 ŞUBAT 2025 | BF2: 6-19 ŞUBAT 2025 | BG2: 20 ŞUBAT-5 MART 2025 | BH2: 6-19 MART 2025 | BI2: 20 MART-2 NİSAN 2025 | BJ2: 3-16 NİSAN 2025 | BK2: 17-30 NİSAN 2025 | BL2: 1-14 MAYIS 2025 | BM2: 15-28 MAYIS 2025 | BN2: 29 MAYIS-11 HAZİRAN 2025 | BO2: 12-25 HAZİRAN 2025 | BP2: 26 HAZİRAN-9 TEMMUZ | BQ2: 10-23 TEMMUZ 2025 | BR2: 24 TEMMUZ-6 AĞUSTOS 2025 | BS2: 7-20 AĞUSTOS 2025 | BT2: 21 AĞUSTOS-10 EYLÜL 2025 | BU2: 11-24 Eylül 2025 | BV2: 25 Eylül-8 Ekim 2025 | BW2: 9-22 Ekim 2025 | BX2: 23 Ekim-5 Kasım 2025 | BY2: 6 -19 Kasım 2025 | BZ2: 20 Kasım-3 Aralık 2025 | CA2: 4-17 Aralık 2025 | CB2: 18 Aralık-14 Ocak 2026 | CC2: 15-28 Ocak 2026 | CD2: 29 Ocak-11 Şubat 2026 | CE2: 12-25 Şubat 2026 | CF2: 26 Şubat-11 Mart 2026 | CG2: 12 Mart-1 Nisan 2026 | CH2: 2-15 Nİsan 2026
A3: İslam | B3: 2.86 | C3: 1.65 | D3: 1.67 | E3: 1.58 | F3: 1.54 | G3: 1.6 | H3: 4.62 | I3: 2.58 | J3: 2.91 | K3: 3.6 | L3: 2.19 | M3: 1.87 | N3: 2.34 | O3: 3.64 | P3: 2.15 | Q3: 1.91 | R3: 3.19 | S3: 1.97 | T3: 2.72 | U3: 2.68 | V3: 2.89 | W3: 1.97 | X3: 3.37 | Y3: 1.8 | Z3: 1.25 | AA3: 1.76 | AB3: 2.27 | AC3: 3.07 | AD3: 1.92 | AE3: 1.43 | AF3: 2.67 | AG3: 3.33 | AH3: 2.42 | AI3: 2.81 | AJ3: 3.13 | AK3: 3.16 | AL3: 2.52 | AM3: 2.1 | AN3: 4.54 | AO3: 2.59 | AP3: 2.81 | AQ3: 2.02 | AR3: 2.39 | AS3: 2.95 | AT3: 3.39 | AU3: 3.54 | AV3: 3 | AW3: 2.29 | AX3: 2.35 | AY3: 1.81 | AZ3: 1.99 | BA3: 2.22 | BB3: 1.43 | BC3: 2.45 | BD3: 2.41 | BE3: 4.11 | BF3: 2.46 | BG3: 2.46 | BH3: 2.83 | BI3: 2.69 | BJ3: 2.77 | BK3: 3.38 | BL3: 2.19 | BM3: 4.24 | BN3: 2.69 | BO3: 3.4 | BP3: 2.95 | BQ3: 2.97 | BR3: 2.84 | BS3: 3.65 | BT3: 3.31 | BU3: 2.51 | BV3: 2.43 | BW3: 2.5 | BX3: 4.24 | BY3: 2.9 | BZ3: 3.56 | CA3: 3.54 | CB3: 3.63 | CC3: 2.76 | CD3: 1.51 | CE3: 2.8 | CF3: 2 | CG3: 2.52 | CH3: 4.94
A4: MuratSaç | B4: 4.71 | C4: 3.66 | D4: 3.89 | E4: 2.4 | F4: 2.48 | G4: 3.21 | H4: 4.62 | I4: 3.87 | J4: 4.94 | K4: 2.93 | L4: 3.62 | M4: 4.81 | N4: 3.03 | O4: 2.26 | P4: 3.59 | Q4: 3.13 | R4: 3.29 | S4: 2.93 | T4: 2.84 | U4: 4.29 | V4: 5.1 | W4: 2.89 | X4: 4.17 | Y4: 0.5 | Z4: 4.79 | AA4: 2.95 | AB4: 4.31 | AC4: 3.7 | AD4: 3.45 | AE4: 3.61 | AF4: 3.08 | AG4: 2.92 | AH4: 3.2 | AI4: 2.76 | AJ4: 4.31 | AK4: 3.66 | AL4: 2.66 | AM4: 3.07 | AN4: 3.05 | AO4: 2.08 | AP4: 4.09 | AQ4: 4.46 | AR4: 4.47 | AS4: 3.89 | AT4: 3.02 | AU4: 4.83 | AV4: 3.06 | AW4: 4.41 | AX4: 3.04 | AY4: 3.25 | AZ4: 3.91 | BA4: 4.51 | BB4: 4.08 | BC4: 5.04 | BD4: 4.95 | BE4: 4.59 | BF4: 3.87 | BG4: 4.98 | BH4: 4.15 | BI4: 4.28 | BJ4: 3.84 | BK4: 4.8 | BL4: 4.21 | BM4: 5.4 | BN4: 3.54 | BO4: 5.34 | BP4: 4.63 | BQ4: 4.34 | BR4: 4.8 | BS4: 3.73 | BT4: 1.84 | BU4: 3.69 | BV4: 3.07 | BW4: 4.19 | BX4: 4.52 | BY4: 3.71 | BZ4: 3.46 | CA4: 5.27 | CB4: 4.65 | CC4: 3.54 | CD4: 5.21 | CE4: 3.44 | CF4: 2.87 | CG4: 3.2 | CH4: 3.01
A5: Emre | B5: 2.61 | C5: 1.76 | D5: 1.76 | E5: 1.76 | F5: 3.44 | G5: 2.69 | H5: 2.6 | I5: 2.87 | J5: 3.54 | K5: 2.65 | L5: 3.11 | M5: 3.06 | N5: 2.38 | O5: 3.78 | P5: 3.25 | Q5: 2.84 | R5: 3.42 | S5: 3.49 | T5: 4.15 | U5: 3.8 | V5: 4.14 | W5: 3.57 | X5: 3.26 | Y5: 4.3 | Z5: 3.27 | AA5: 4 | AB5: 4 | AC5: 4 | AD5: 3.2 | AE5: 2.51 | AF5: 3.63 | AG5: 3.96 | AH5: 3.15 | AI5: 3.89 | AJ5: 3.06 | AK5: 3.27 | AL5: 3.34 | AM5: 3.32 | AN5: 3.76 | AO5: 2.21 | AP5: 3.57 | AQ5: 2.58 | AR5: 3.04 | AS5: 3.36 | AT5: 4.26 | AU5: 4.04 | AV5: 3.49 | AW5: 3.4 | AX5: 3.31 | AY5: 2.77 | AZ5: 3.8 | BA5: 3.72 | BB5: 3.75 | BC5: 3.25 | BD5: 3.82 | BE5: 2.27 | BF5: 3.28 | BG5: 3.36 | BH5: 2.96 | BI5: 3.28 | BJ5: 4.11 | BK5: 3.68 | BL5: 3.88 | BM5: 3.74 | BN5: 3.74 | BO5: 3.84 | BP5: 2.74 | BQ5: 3.57 | BR5: 3.55 | BS5: 3.79 | BT5: 4.15 | BU5: 3.43 | BV5: 4.14 | BW5: 3.2 | BX5: 4 | BY5: 3.3 | BZ5: 3.6 | CA5: 3.45 | CB5: 3.4 | CC5: 3.05 | CD5: 3.23 | CE5: 3.16 | CF5: 3.7 | CG5: 3.61 | CH5: 3.24
A6: Devrim | B6: 2.19 | C6: 2.33 | D6: 1.89 | E6: 2.56 | F6: 1.75 | G6: 2.78 | H6: 1.87 | I6: 2.3 | J6: 2.97 | K6: 3.52 | L6: 3.13 | M6: 2.35 | N6: 2.12 | O6: 2.09 | P6: 1.53 | Q6: 2.03
A7: Farhad | B7: 3.53 | C7: 4.56 | D7: 4.45 | E7: 4.12 | F7: 5.03 | G7: 3.92 | H7: 4.04 | I7: 2.54 | J7: 4.85 | K7: 3.69 | L7: 5.31 | M7: 4.14 | N7: 3.08 | O7: 4.57 | P7: 4.33 | Q7: 5.29 | R7: 2.92 | S7: 5.07 | T7: 4.39 | U7: 4.69 | V7: 4.13 | W7: 3.06 | X7: 5.55 | Y7: 3.07 | Z7: 5.08 | AA7: 5.25 | AB7: 5.59 | AC7: 4.25 | AD7: 3.42 | AE7: 5.22 | AF7: 4.35 | AG7: 2.65 | AH7: 3.65 | AI7: 3.68 | AJ7: 4.24 | AK7: 4.08 | AL7: 5.23 | AM7: 4.54 | AN7: 4.25 | AO7: 4.76 | AP7: 5.17 | AQ7: 4.04 | AR7: 5.23 | AS7: 3.07 | AT7: 4.95 | AU7: 4.94 | AV7: 4.23 | AW7: 4.47 | AX7: 4.02 | AY7: 3.99 | AZ7: 4.4 | BA7: 3.68 | BB7: 4.1 | BC7: 4.46 | BD7: 4.56 | BE7: 5.19 | BF7: 4.2 | BG7: 3.85 | BH7: 5.52 | BI7: 3.4 | BJ7: 5.35 | BK7: 5.43 | BL7: 4.24 | BM7: 4.66 | BO7: 4.34 | BP7: 5.05 | BQ7: 4.99 | BR7: 3.5 | BS7: 3.38 | BT7: 4.54 | BU7: 4.58 | BV7: 4.05 | BW7: 5.34 | BX7: 3.21 | BY7: 4.73 | BZ7: 4.71 | CA7: 4.13 | CB7: 4.38 | CC7: 3.32 | CD7: 4.98 | CE7: 4.69 | CF7: 4.27 | CG7: 4.78 | CH7: 4.32
A8: Ömer | B8: 1.73 | C8: 4.57 | D8: 3.76 | E8: 4.21 | F8: 4.03 | G8: 3.58 | H8: 2.87 | I8: 3.18 | J8: 4.35 | K8: 4.73 | L8: 4.07 | M8: 1.86 | N8: 2.34 | O8: 2.22 | P8: 3.58 | Q8: 3.69 | R8: 3.19 | S8: 3.34 | T8: 2.9 | U8: 2.72 | V8: 2.73 | W8: 2.16 | X8: 3.14 | Y8: 1.35 | Z8: 2.12 | AA8: 3.17 | AB8: 2.51 | AC8: 3.09 | AD8: 2.52 | AE8: 2.84 | AF8: 2.43 | AG8: 2.78 | AH8: 1.68 | AI8: 2.2 | AJ8: 2.61 | AK8: 3 | AL8: 2.44 | AM8: 2.22 | AN8: 3.64 | AO8: 3.26 | AP8: 2.71 | AQ8: 1.81 | AR8: 2.92 | AS8: 2.95 | AT8: 1.94 | AU8: 1.9 | AV8: 1.71 | AW8: 2.3 | AX8: 2.69 | AY8: 2.21 | AZ8: 2.49 | BA8: 3.17 | BB8: 1.84 | BC8: 2.11 | BD8: 2.93 | BE8: 2.63 | BF8: 2.98 | BG8: 1.96 | BH8: 3.2 | BI8: 3.39 | BJ8: 4.29 | BK8: 2.97 | BL8: 3.14 | BM8: 3.23 | BN8: 2.42 | BO8: 2.92 | BP8: 2.61 | BQ8: 4.57
A9: Batuhan | B9: 2.41 | C9: 3.05 | D9: 1.73 | E9: 3.52 | F9: 1.59 | G9: 1.69 | H9: 1.68 | I9: 1.96 | J9: 2.97 | K9: 1.78 | L9: 3.24 | M9: 3.55 | N9: 2.24 | O9: 2.87 | P9: 2.69 | Q9: 2.26
A10: Malik | B10: 2.58 | C10: 4.75 | D10: 4.37 | E10: 4.5 | F10: 3.41 | G10: 3.02 | H10: 1.64 | I10: 3.87 | J10: 3.01 | K10: 3.57 | L10: 3.48 | M10: 3.27 | N10: 3.52 | O10: 3.21 | P10: 3.59 | Q10: 2.75 | R10: 3.26 | S10: 4.45 | T10: 4.74 | U10: 4.01 | V10: 4.29 | W10: 2.33 | X10: 3.58 | Y10: 3.75 | Z10: 3.36 | AA10: 3.38 | AB10: 3.53 | AC10: 4.48 | AD10: 3.06 | AE10: 3.7 | AF10: 4.5 | AG10: 3.92 | AH10: 1.56 | AI10: 2.52 | AJ10: 4.09 | AK10: 4.87 | AL10: 3.15 | AM10: 3.9 | AN10: 4.25 | AO10: 2.67 | AP10: 2.61 | AQ10: 3.55 | AR10: 3.64 | AS10: 2.45 | AT10: 3.58 | AU10: 2.66 | AV10: 3.26 | AW10: 4.52 | AX10: 3.7 | AY10: 4.26 | AZ10: 4.09 | BA10: 2.49 | BB10: 4.06 | BC10: 3.35 | BD10: 3.87 | BE10: 3.16 | BF10: 3.1 | BG10: 4.71 | BH10: 3.8 | BI10: 4.95 | BJ10: 4.43 | BK10: 3.07 | BL10: 4.97 | BM10: 4.79 | BN10: 3.17 | BO10: 3.85 | BP10: 4.2 | BQ10: 4.57 | BR10: 3.85 | BS10: 4.87 | BT10: 2.27 | BU10: 4.46 | BV10: 5.12 | BW10: 4.91 | BX10: 4.66 | BY10: 3.91 | BZ10: 2.86 | CA10: 5.22 | CB10: 3.66 | CC10: 3.27 | CD10: 3.09 | CE10: 3.68 | CF10: 3.32 | CG10: 3.38 | CH10: 2.22
A11: Yasemin | S11: 2.52 | T11: 2.28 | U11: 2.1 | V11: 2.38 | W11: 1.27 | X11: 0.87 | Y11: 2.36 | Z11: 1.14
A12: Yılmaz | T12: 2.07 | U12: 4.13 | V12: 0 | W12: 3.98 | X12: 3.43 | Y12: 4.53 | Z12: 1.27 | AA12: 3.03 | AB12: 2.9 | AC12: 3.32 | AD12: 3.01 | AE12: 3.25 | AF12: 2.59 | AG12: 2.79 | AH12: 2.33 | AI12: 4.5 | AJ12: 3.81 | AK12: 3.73 | AL12: 2.02 | AM12: 4.33 | AN12: 4.43 | AO12: 3.37 | AP12: 4.05 | AQ12: 2.33 | AR12: 2.27 | AS12: 2.16 | AT12: 3.92 | AU12: 3.32 | AV12: 4.2 | AW12: 3.33 | AX12: 3.34 | AY12: 3.48 | AZ12: 3.42 | BA12: 3.39 | BB12: 2.98 | BC12: 4.33 | BD12: 5.42 | BE12: 4.52 | BF12: 5.44 | BG12: 4.23 | BH12: 4.38 | BI12: 4.05 | BJ12: 4.56 | BK12: 4.59 | BL12: 4.42 | BM12: 3.31 | BN12: 2.78 | BO12: 3.77 | BP12: 3.27 | BQ12: 5.27 | BR12: 5.08 | BS12: 3.03 | BT12: 2.59 | BU12: 4.03 | BV12: 3.73 | BW12: 4.18 | BX12: 3.93 | BY12: 2.75 | BZ12: 3.62 | CA12: 3.09 | CB12: 3.18 | CC12: 2.73 | CD12: 3.53 | CE12: 3.69 | CF12: 4.21 | CG12: 3.61 | CH12: 3.58
A14: Furkan | BT14: 1.42 | BU14: 2.58 | BV14: 1.5 | BW14: 2.4 | BX14: 2.32 | BY14: 3.42 | BZ14: 1.64 | CA14: 1.64 | CB14: 2.19 | CC14: 2.46 | CD14: 2.21 | CE14: 2.45 | CF14: 2.5 | CG14: 1.64 | CH14: 2.21
A16: EKİP ORTALAMASI | B16: =(B3+B5+B6+B7+B9+B10)/6 -> 2.6966667 | C16: =(C4+C5+C6+C7+C8+C9)/6 -> 3.3216667 | D16: =(D4+D5+D6+D10+D8+D9)/6 -> 2.9 | E16: =(E4+E5+E6+E7+E8+E9)/6 -> 3.095 | F16: =(F4+F5+F6+F10+F8+F9)/6 -> 2.7833333 | G16: =(G4+G5+G6+G10+G8+G9)/6 -> 2.8283333 | H16: 2.61 | I16: 2.69 | J16: 3.61 | K16: 3.33 | L16: 3.44 | M16: 3.04 | N16: 2.57 | O16: 3 | P16: 3.14 | Q16: 2.78 | R16: 3.23 | S16: 3.35 | T16: 3.21 | U16: 3.61 | V16: 3.64 | W16: 2.66 | X16: 3.49 | Y16: 3.06 | Z16: 2.68 | AA16: 3.31 | AB16: 3.45 | AC16: 3.67 | AD16: 3.05 | AE16: 3.16 | AF16: 3.26 | AG16: 3.15 | AH16: 2.4 | AI16: 3.13 | AJ16: 3.67 | AK16: 3.58 | AL16: 2.82 | AM16: 3.41 | AN16: 4.06 | AO16: 2.82 | AP16: 3.45 | AQ16: 2.9 | AR16: 3.29 | AS16: 3.14 | AT16: 3.63 | AU16: 3.68 | AV16: 3.4 | AW16: 3.58 | AX16: 3.22 | AY16: 3.14 | AZ16: 3.54 | BA16: 3.29 | BB16: 3.34 | BC16: 3.57 | BD16: 4.03 | BE16: 3.8 | BF16: 3.49 | BG16: 3.72 | BH16: 3.7 | BI16: 3.68 | BJ16: 4.24 | BK16: 3.9 | BL16: 3.98 | BM16: 4.15 | BN16: 3.05 | BO16: 3.84 | BP16: 3.66 | BQ16: 4.37 | BR16: 3.93 | BS16: 3.64 | BT16: 2.83 | BU16: 3.58 | BV16: 3.49 | BW16: 3.8 | BX16: 3.98 | BY16: 3.45 | BZ16: 3.42 | CA16: 3.88 | CB16: 3.65 | CC16: 3.02 | CD16: 3.41 | CE16: 3.36 | CF16: 3.37 | CG16: 3.26 | CH16: 3.27
A18: Kudo şampiyonu | B18: Devrim | C18: Malik | D18: Malik | E18: Ömer | F18: Emre, Farhad, Malik | G18: Farhad | H18: Farhad | I18: Devrim-Batuhan-Malik | J18: Emre | K18: Devrim-farhad-ömer-malik | L18: devrim | M18: islam | N18: farhad | O18: islam | P18: farhad | Q18: farhad | R18: Malik | S18: Yasemin | T18: Emre-Malik | U18: Yılmaz | V18: Malik-Murat | W18: Emre | X18: Farhad | Y18: Murat | Z18: Murat | AA18: Farhad-Ömer | AB18: Farhad | AC18: Malik | AD18: Selim | AE18: Farhad | AF18: Malik | AG18: Malik | AH18: Emre | AI18: İslam | AJ18: Yılmaz | AK18: Malik | AL18: Malik | AM18: HERKES | AN18: Yılmaz | AO18: İslam-Farhad | AP18: batuhan | AQ18: farhad-malik | AR18: Murat | AS18: YAPILMADI | AT18: Yılmaz | AU18: yapılmadı | AV18: İslam | AW18: Özge | AX18: Emre | AY18: Malik-Yılmaz | AZ18: Emre | BA18: Emre | BB18: Emre | BC18: Melis | BD18: Burak | BE18: Farhad | BF18: Yılmaz | BG18: Nazlı | BH18: Farhad | BI18: Burak | BJ18: Ömer-Yılmaz | BK18: Burak | BL18: Malik | BM18: Ömer-Emre-İslam-Malik | BN18: Emre | BO18: Emre | BP18: Farhad | BQ18: Yılmaz | BR18: Murat-Yılmaz | BS18: Malik | BT18: Emre | BU18: - | BV18: Malik | BW18: Malik | BX18: Malik-Yılmaz | BY18: Malik | BZ18: Emre-Farhad | CA18: Malik | CB18: Farhad | CC18: İslam-Malik | CD18: Murat | CE18: - | CF18: Emre | CG18: Farhad | CH18: İslam
A19: KPI Şampiyonu | B19: Murat | C19: Malik | D19: Farhad | E19: Malik | F19: Farhad | G19: Farhad | H19: İslam-Murat | I19: Malik-Murat | J19: Murat | K19: Ömer | L19: farhad | M19: murat | N19: malik | O19: farhad | P19: farhad | Q19: farhad | R19: Emre | S19: Farhad | T19: Malik | U19: Farhad | V19: Murat | W19: Yılmaz | X19: Farhad | Y19: Yılmaz | Z19: Farhad | AA19: Farhad | AB19: Farhad | AC19: Malik | AD19: Murat | AE19: Farhad | AF19: Malik | AG19: Emre | AH19: Farhad | AI19: Yılmaz | AJ19: Murat | AK19: Malik | AL19: Farhad | AM19: Farhad | AN19: İslam | AO19: Farhad | AP19: Farhad | AQ19: murat | AR19: Farhad | AS19: Farhad | AT19: Farhad | AU19: Farhad | AV19: Farhad | AW19: Malik | AX19: Farhad | AY19: Malik | AZ19: Farhad | BA19: Murat | BB19: Farhad | BC19: Murat | BD19: Yılmaz | BE19: İslam | BF19: Yılmaz | BG19: Murat | BH19: Farhad | BI19: Malik | BJ19: Farhad | BK19: Farhad | BL19: Malik | BM19: Murat | BN19: Emre | BO19: Murat | BP19: Farhad | BQ19: Yılmaz | BR19: Yılmaz | BS19: Malik | BT19: Farhad | BU19: Farhad | BV19: Malik | BW19: Farhad | BX19: Malik | BY19: Farhad | BZ19: Farhad | CA19: Murat | CB19: Murat | CC19: Murat | CD19: Murat | CE19: Farhad | CF19: Farhad | CG19: Farhad | CH19: İslam
AV21: 2-6 EYLÜL IT CAMP
K23: 1 | L23: 1 | M23: 1 | N23: 1 | BM23: 2022-2023-2024 VERİLERİ GİZLENMİŞTİR, | BR23: en düşük
K24: 1 | L24: 1 | BM24: İHTİYAÇ HALİNDE AÇABİLİRSİNİZ | BR24: ortalama altı
BR25: en yüksek
G31: kpı
G32: farhad | H32: 1 | I32: 1 | J32: 1 | K32: 1 | L32: 1 | M32: 1 | N32: 1 | O32: 1
G33: islam | H33: 1
G34: murat | H34: 1 | I34: 1 | J34: 1 | K34: 1
G35: malik | H35: 1 | I35: 1 | J35: 1
G36: ömer | H36: 1
G37: emre | H37: 1

Sheet 2024
E1: KODLANAN MADDE SAYISI
E2: 45593 | F2: 45579 | G2: 45565 | H2: 45915 | I2: 45901 | J2: 45509 | L2: 45481 | O2: 20 MAYIS | U2: 45341 | AA2: 2024 | AC2: 11 ARALIK | AG2: 45581 | AK2: 45518 | AO2: 12 HAZİRAN | AR2: 2 MAYIS | AV2: 45371 | AX2: 45342
A3: İslam | B3: ='9-22 Aralık 2024'!B2 -> 1 | C3: ='25 Kasım-8 Aralık 2024'!B2 -> 7 | D3: ='11_24 Kasım 2024'!B2 -> 9 | E3: ='30 Ekim-10 Kasım 2024'!B2 -> 5 | F3: ='14_29 Ekim 2024'!B2 -> 9 | G3: ='30 Eylül-13 Ekim 2024'!B2 -> 10 | H3: ='2-29 Eylül 2024'!B2 -> 8 | I3: ='19-30 Ağustos 2024'!B2 -> 4 | J3: ='5-18 Ağustos 2024'!B2 -> 3 | K3: ='22 Temmuz-4 Ağustos 2024'!B2 -> 5 | L3: ='8-21 Temmuz 2024'!B2 -> 5 | M3: ='17 Haziran-7 Temmuz 2024'!B2 -> 4 | N3: ='3-16 Haziran 2024'!B2 -> 4 | O3: ='20 Mayıs-2 Haziran 2024'!B2 -> 1 | P3: ='6-19 MAYIS'!B2 -> 8 | Q3: ='22 NİSAN-5 MAYIS'!B2 -> 6 | R3: ='1-21 Nisan 2024'!B2 -> 4 | S3: ='18-31 Mart 2024'!B2 -> 3 | T3: ='4-17 Mart 2024'!B2 -> 6 | U3: ='19 şubat-3 Mart 2024'!B2 -> 13 | V3: ='5 şubat-18 Şubat 2024'!B2 -> 9 | W3: ='22 Ocak-4 Şubat 2024'!B2 -> 12 | X3: ='8 Ocak-21 Ocak 2024'!B2 -> 6 | Y3: ='25Aralık 2023-7 Ocak 2024'!B2 -> 1 | AA3: =SUM(D3:Y3) -> 135 | AC3: ='11 Aralık-24Aralık 2023'!B2 -> 7 | AD3: ='27 Kasım-10 Aralık'!B2 -> 5 | AE3: ='13 Kasım-26 Kasım'!B2 -> 11 | AF3: ='30 Ekim-12 Kasım'!B2 -> 14 | AG3: ='16-29 Ekim'!B2 -> 5 | AH3: ='2 Ekim-15 Ekim 2023 '!B2 -> 7 | AI3: ='18 Eylül-1 Ekim 2023'!B2 -> 4 | AJ3: ='28 Ağustos-17 Eylül 2023'!B2 -> 5 | AK3: ='14-27 Ağustos'!B2 -> 8 | AL3: ='31 Temmuz-13 Ağustos'!B2 -> 13 | AM3: ='17 Temmuz-30 Temmuz 2023'!B2 -> 8 | AN3: ='26 Haziran-16Temmuz 2023'!B2 -> 9 | AO3: ='12-25 Haziran 2023'!B2 -> 11 | AP3: ='29 mayıs-11 Haziran 2023'!B2 -> 6 | AQ3: ='15 mayıs-28 mayıs 2023'!B2 -> 10 | AR3: ='2 mayıs-14 mayıs 2023'!B2 -> 13 | AS3: ='17 nisan-1 mayıs 2023'!B2 -> 5 | AT3: ='17 nisan-1 mayıs 2023'!B2 -> 5 | AU3: ='3-16 nisan 2023'!B2 -> 2 | AV3: ='20 Mart-2 nisan 2023'!B2 -> 5 | AW3: ='6 mart-19 mart 2023'!B2 -> 12 | AX3: ='20 şubat-5 mart 2023'!B2 -> 9 | AY3: ='23 ocak-17 şubat'!B2 -> 16 | AZ3: ='26 aralık-20 ocak'!B2 -> 11 | BB3: =SUM(AC3:AZ3) -> 201
A4: MuratSaç | B4: ='9-22 Aralık 2024'!B3 -> 3 | C4: ='25 Kasım-8 Aralık 2024'!B3 -> 6 | D4: ='11_24 Kasım 2024'!B3 -> 10 | E4: ='30 Ekim-10 Kasım 2024'!B3 -> 5 | F4: ='14_29 Ekim 2024'!B3 -> 8 | G4: ='30 Eylül-13 Ekim 2024'!B3 -> 2 | H4: ='2-29 Eylül 2024'!B3 -> 8 | I4: ='19-30 Ağustos 2024'!B3 -> 4 | J4: ='5-18 Ağustos 2024'!B3 -> 3 | K4: ='22 Temmuz-4 Ağustos 2024'!B3 -> 1 | L4: ='8-21 Temmuz 2024'!B3 -> 1 | M4: ='17 Haziran-7 Temmuz 2024'!B3 -> 1 | N4: ='3-16 Haziran 2024'!B3 -> 6 | O4: ='20 Mayıs-2 Haziran 2024'!B3 -> 3 | P4: ='6-19 MAYIS'!B3 -> 4 | Q4: ='22 NİSAN-5 MAYIS'!B3 -> 3 | R4: ='1-21 Nisan 2024'!B3 -> 4 | S4: ='18-31 Mart 2024'!B3 -> 1 | T4: ='4-17 Mart 2024'!B3 -> 4 | U4: ='19 şubat-3 Mart 2024'!B3 -> 4 | V4: ='5 şubat-18 Şubat 2024'!B3 -> 1 | W4: ='22 Ocak-4 Şubat 2024'!B3 -> 2 | X4: ='8 Ocak-21 Ocak 2024'!B3 -> 4 | Y4: ='25Aralık 2023-7 Ocak 2024'!B3 -> 3 | AA4: =SUM(D4:Y4) -> 82 | AC4: ='11 Aralık-24Aralık 2023'!B3 -> 6 | AD4: ='27 Kasım-10 Aralık'!B3 -> 2 | AE4: ='13 Kasım-26 Kasım'!B3 -> 5 | AF4: ='30 Ekim-12 Kasım'!B3 -> 4 | AG4: ='16-29 Ekim'!B3 -> 7 | AH4: ='2 Ekim-15 Ekim 2023 '!B3 -> 0 | AI4: ='18 Eylül-1 Ekim 2023'!B3 -> 4 | AJ4: ='28 Ağustos-17 Eylül 2023'!B3 -> 3 | AK4: ='14-27 Ağustos'!B3 -> 6 | AL4: ='31 Temmuz-13 Ağustos'!B3 -> 9 | AM4: ='17 Temmuz-30 Temmuz 2023'!B3 -> 4 | AN4: ='26 Haziran-16Temmuz 2023'!B3 -> 3 | AO4: ='12-25 Haziran 2023'!B3 -> 7 | AP4: ='29 mayıs-11 Haziran 2023'!B3 -> 8 | AQ4: ='15 mayıs-28 mayıs 2023'!B3 -> 10 | AR4: ='2 mayıs-14 mayıs 2023'!B3 -> 5 | AS4: ='17 nisan-1 mayıs 2023'!B3 -> 8 | AT4: ='17 nisan-1 mayıs 2023'!B3 -> 8 | AU4: ='3-16 nisan 2023'!B3 -> 11 | AV4: ='20 Mart-2 nisan 2023'!B3 -> 8 | AW4: ='6 mart-19 mart 2023'!B3 -> 6 | AX4: ='20 şubat-5 mart 2023'!B3 -> 11 | AY4: ='23 ocak-17 şubat'!B3 -> 24 | AZ4: ='26 aralık-20 ocak'!B3 -> 18 | BB4: =SUM(AC4:AZ4) -> 177
A5: Emre | B5: ='9-22 Aralık 2024'!B4 -> 16 | C5: ='25 Kasım-8 Aralık 2024'!B4 -> 15 | D5: ='11_24 Kasım 2024'!B4 -> 13 | E5: ='30 Ekim-10 Kasım 2024'!B4 -> 5 | F5: ='14_29 Ekim 2024'!B4 -> 17 | G5: ='30 Eylül-13 Ekim 2024'!B4 -> 16 | H5: ='2-29 Eylül 2024'!B4 -> 10 | I5: ='19-30 Ağustos 2024'!B4 -> 10 | J5: ='5-18 Ağustos 2024'!B4 -> 9 | K5: ='22 Temmuz-4 Ağustos 2024'!B4 -> 16 | L5: ='8-21 Temmuz 2024'!B4 -> 21 | M5: ='17 Haziran-7 Temmuz 2024'!B4 -> 13 | N5: ='3-16 Haziran 2024'!B4 -> 17 | O5: ='20 Mayıs-2 Haziran 2024'!B4 -> 9 | P5: ='6-19 MAYIS'!B4 -> 12 | Q5: ='22 NİSAN-5 MAYIS'!B4 -> 12 | R5: ='1-21 Nisan 2024'!B4 -> 6 | S5: ='18-31 Mart 2024'!B4 -> 18 | T5: ='4-17 Mart 2024'!B4 -> 15 | U5: ='19 şubat-3 Mart 2024'!B4 -> 13 | V5: ='5 şubat-18 Şubat 2024'!B4 -> 10 | W5: ='22 Ocak-4 Şubat 2024'!B4 -> 15 | X5: ='8 Ocak-21 Ocak 2024'!B4 -> 14 | Y5: ='25Aralık 2023-7 Ocak 2024'!B4 -> 9 | AA5: =SUM(D5:Y5) -> 280 | AC5: ='11 Aralık-24Aralık 2023'!B4 -> 11 | AD5: ='27 Kasım-10 Aralık'!B4 -> 17 | AE5: ='13 Kasım-26 Kasım'!B4 -> 14 | AF5: ='30 Ekim-12 Kasım'!B4 -> 15 | AG5: ='16-29 Ekim'!B4 -> 5 | AH5: ='2 Ekim-15 Ekim 2023 '!B4 -> 4 | AI5: ='18 Eylül-1 Ekim 2023'!B4 -> 8 | AJ5: ='28 Ağustos-17 Eylül 2023'!B4 -> 11 | AK5: ='14-27 Ağustos'!B4 -> 10 | AL5: ='31 Temmuz-13 Ağustos'!B4 -> 8 | AM5: ='17 Temmuz-30 Temmuz 2023'!B4 -> 14 | AN5: ='26 Haziran-16Temmuz 2023'!B4 -> 13 | AO5: ='12-25 Haziran 2023'!B4 -> 13 | AP5: ='29 mayıs-11 Haziran 2023'!B4 -> 11 | AQ5: ='15 mayıs-28 mayıs 2023'!B4 -> 14 | AR5: ='2 mayıs-14 mayıs 2023'!B4 -> 10 | AS5: ='17 nisan-1 mayıs 2023'!B4 -> 9 | AT5: ='17 nisan-1 mayıs 2023'!B4 -> 9 | AU5: ='3-16 nisan 2023'!B4 -> 17 | AV5: ='20 Mart-2 nisan 2023'!B4 -> 6 | AW5: ='6 mart-19 mart 2023'!B4 -> 13 | AX5: ='20 şubat-5 mart 2023'!B4 -> 18 | AY5: ='23 ocak-17 şubat'!B4 -> 24 | AZ5: ='26 aralık-20 ocak'!B4 -> 15 | BB5: =SUM(AC5:AZ5) -> 289
A6: Farhad | B6: ='9-22 Aralık 2024'!B5 -> 5 | C6: ='25 Kasım-8 Aralık 2024'!B5 -> 5 | D6: ='11_24 Kasım 2024'!B5 -> 12 | E6: ='30 Ekim-10 Kasım 2024'!B5 -> 12 | F6: ='14_29 Ekim 2024'!B5 -> 16 | G6: ='30 Eylül-13 Ekim 2024'!B5 -> 9 | H6: ='2-29 Eylül 2024'!B5 -> 23 | I6: ='19-30 Ağustos 2024'!B5 -> 2 | J6: ='5-18 Ağustos 2024'!B5 -> 5 | K6: ='22 Temmuz-4 Ağustos 2024'!B5 -> 12 | L6: ='8-21 Temmuz 2024'!B5 -> 8 | M6: ='17 Haziran-7 Temmuz 2024'!B5 -> 5 | N6: ='3-16 Haziran 2024'!B5 -> 2 | O6: ='20 Mayıs-2 Haziran 2024'!B5 -> 1 | P6: ='6-19 MAYIS'!B5 -> 5 | Q6: ='22 NİSAN-5 MAYIS'!B5 -> 2 | R6: ='1-21 Nisan 2024'!B5 -> 6 | S6: ='18-31 Mart 2024'!B5 -> 6 | T6: ='4-17 Mart 2024'!B5 -> 4 | U6: ='19 şubat-3 Mart 2024'!B5 -> 6 | V6: ='5 şubat-18 Şubat 2024'!B5 -> 7 | W6: ='22 Ocak-4 Şubat 2024'!B5 -> 2 | X6: ='8 Ocak-21 Ocak 2024'!B5 -> 6 | Y6: ='25Aralık 2023-7 Ocak 2024'!B5 -> 7 | AA6: =SUM(D6:Y6) -> 158 | AC6: ='11 Aralık-24Aralık 2023'!B5 -> 4 | AD6: ='27 Kasım-10 Aralık'!B5 -> 7 | AE6: ='13 Kasım-26 Kasım'!B5 -> 1 | AF6: ='30 Ekim-12 Kasım'!B5 -> 8 | AG6: ='16-29 Ekim'!B5 -> 8 | AH6: ='2 Ekim-15 Ekim 2023 '!B5 -> 6 | AI6: ='18 Eylül-1 Ekim 2023'!B5 -> 8 | AJ6: ='28 Ağustos-17 Eylül 2023'!B5 -> 5 | AK6: ='14-27 Ağustos'!B5 -> 2 | AL6: ='31 Temmuz-13 Ağustos'!B5 -> 5 | AM6: ='17 Temmuz-30 Temmuz 2023'!B5 -> 4 | AN6: ='26 Haziran-16Temmuz 2023'!B5 -> 7 | AO6: ='12-25 Haziran 2023'!B5 -> 4 | AP6: ='29 mayıs-11 Haziran 2023'!B5 -> 12 | AQ6: ='15 mayıs-28 mayıs 2023'!B5 -> 8 | AR6: ='2 mayıs-14 mayıs 2023'!B5 -> 14 | AS6: ='17 nisan-1 mayıs 2023'!B5 -> 8 | AT6: ='17 nisan-1 mayıs 2023'!B5 -> 8 | AU6: ='3-16 nisan 2023'!B5 -> 5 | AV6: ='20 Mart-2 nisan 2023'!B5 -> 6 | AW6: ='6 mart-19 mart 2023'!B5 -> 10 | AX6: ='20 şubat-5 mart 2023'!B5 -> 6 | AY6: ='23 ocak-17 şubat'!B5 -> 16 | AZ6: ='26 aralık-20 ocak'!B5 -> 19 | BB6: =SUM(AC6:AZ6) -> 181
A7: Ömer | B7: ='9-22 Aralık 2024'!B6 -> 8 | C7: ='25 Kasım-8 Aralık 2024'!B6 -> 11 | D7: ='11_24 Kasım 2024'!B6 -> 14 | E7: ='30 Ekim-10 Kasım 2024'!B6 -> 13 | F7: ='14_29 Ekim 2024'!B6 -> 9 | G7: ='30 Eylül-13 Ekim 2024'!B6 -> 11 | H7: ='2-29 Eylül 2024'!B6 -> 11 | I7: ='19-30 Ağustos 2024'!B6 -> 5 | J7: ='5-18 Ağustos 2024'!B6 -> 9 | K7: ='22 Temmuz-4 Ağustos 2024'!B6 -> 8 | L7: ='8-21 Temmuz 2024'!B6 -> 12 | M7: ='17 Haziran-7 Temmuz 2024'!B6 -> 5 | N7: ='3-16 Haziran 2024'!B6 -> 12 | O7: ='20 Mayıs-2 Haziran 2024'!B6 -> 9 | P7: ='6-19 MAYIS'!B6 -> 11 | Q7: ='22 NİSAN-5 MAYIS'!B6 -> 10 | R7: ='1-21 Nisan 2024'!B6 -> 16 | S7: ='18-31 Mart 2024'!B6 -> 8 | T7: ='4-17 Mart 2024'!B6 -> 17 | U7: ='19 şubat-3 Mart 2024'!B6 -> 11 | V7: ='5 şubat-18 Şubat 2024'!B6 -> 9 | W7: ='22 Ocak-4 Şubat 2024'!B6 -> 17 | X7: ='8 Ocak-21 Ocak 2024'!B6 -> 11 | Y7: ='25Aralık 2023-7 Ocak 2024'!B6 -> 18 | AA7: =SUM(D7:Y7) -> 246 | AC7: ='11 Aralık-24Aralık 2023'!B6 -> 9 | AD7: ='27 Kasım-10 Aralık'!B6 -> 16 | AE7: ='13 Kasım-26 Kasım'!B6 -> 12 | AF7: ='30 Ekim-12 Kasım'!B6 -> 16 | AG7: ='16-29 Ekim'!B6 -> 7 | AH7: ='2 Ekim-15 Ekim 2023 '!B6 -> 2 | AI7: ='18 Eylül-1 Ekim 2023'!B6 -> 9 | AJ7: ='28 Ağustos-17 Eylül 2023'!B6 -> 12 | AK7: ='14-27 Ağustos'!B6 -> 7 | AL7: ='31 Temmuz-13 Ağustos'!B6 -> 7 | AM7: ='17 Temmuz-30 Temmuz 2023'!B6 -> 1 | AN7: ='26 Haziran-16Temmuz 2023'!B6 -> 12 | AO7: ='12-25 Haziran 2023'!B6 -> 15 | AP7: ='29 mayıs-11 Haziran 2023'!B6 -> 14 | AQ7: ='15 mayıs-28 mayıs 2023'!B6 -> 15 | AR7: ='2 mayıs-14 mayıs 2023'!B6 -> 10 | AS7: ='17 nisan-1 mayıs 2023'!B6 -> 7 | AT7: ='17 nisan-1 mayıs 2023'!B6 -> 7 | AU7: ='3-16 nisan 2023'!B6 -> 7 | AV7: ='20 Mart-2 nisan 2023'!B6 -> 5 | AW7: ='6 mart-19 mart 2023'!B6 -> 16 | AX7: ='20 şubat-5 mart 2023'!B6 -> 14 | AY7: ='23 ocak-17 şubat'!B6 -> 18 | AZ7: ='26 aralık-20 ocak'!B6 -> 20 | BB7: =SUM(AC7:AZ7) -> 258
A8: Malik | B8: ='9-22 Aralık 2024'!B7 -> 9 | C8: ='25 Kasım-8 Aralık 2024'!B7 -> 3 | D8: ='11_24 Kasım 2024'!B7 -> 8 | E8: ='30 Ekim-10 Kasım 2024'!B7 -> 13 | F8: ='14_29 Ekim 2024'!B7 -> 12 | G8: ='30 Eylül-13 Ekim 2024'!B7 -> 3 | H8: ='2-29 Eylül 2024'!B7 -> 5 | I8: ='19-30 Ağustos 2024'!B7 -> 8 | J8: ='5-18 Ağustos 2024'!B7 -> 13 | K8: ='22 Temmuz-4 Ağustos 2024'!B7 -> 3 | L8: ='8-21 Temmuz 2024'!B7 -> 2 | M8: ='17 Haziran-7 Temmuz 2024'!B7 -> 5 | N8: ='3-16 Haziran 2024'!B7 -> 5 | O8: ='20 Mayıs-2 Haziran 2024'!B7 -> 1 | P8: ='6-19 MAYIS'!B7 -> 4 | Q8: ='22 NİSAN-5 MAYIS'!B7 -> 7 | R8: ='1-21 Nisan 2024'!B7 -> 12 | S8: ='18-31 Mart 2024'!B7 -> 16 | T8: ='4-17 Mart 2024'!B7 -> 7 | U8: ='19 şubat-3 Mart 2024'!B7 -> 9 | V8: ='5 şubat-18 Şubat 2024'!B7 -> 4 | W8: ='22 Ocak-4 Şubat 2024'!B7 -> 10 | X8: ='8 Ocak-21 Ocak 2024'!B7 -> 7 | Y8: ='25Aralık 2023-7 Ocak 2024'!B7 -> 8 | AA8: =SUM(D8:Y8) -> 162 | AC8: ='11 Aralık-24Aralık 2023'!B7 -> 8 | AD8: ='27 Kasım-10 Aralık'!B7 -> 10 | AE8: ='13 Kasım-26 Kasım'!B7 -> 6 | AF8: ='30 Ekim-12 Kasım'!B7 -> 5 | AG8: ='16-29 Ekim'!B7 -> 4 | AH8: ='2 Ekim-15 Ekim 2023 '!B7 -> 7 | AI8: ='18 Eylül-1 Ekim 2023'!B7 -> 6 | AJ8: ='28 Ağustos-17 Eylül 2023'!B7 -> 4 | AK8: ='14-27 Ağustos'!B7 -> 9 | AL8: ='31 Temmuz-13 Ağustos'!B7 -> 6 | AM8: ='17 Temmuz-30 Temmuz 2023'!B7 -> 10 | AN8: ='26 Haziran-16Temmuz 2023'!B7 -> 11 | AO8: ='12-25 Haziran 2023'!B7 -> 5 | AP8: ='29 mayıs-11 Haziran 2023'!B7 -> 5 | AQ8: ='15 mayıs-28 mayıs 2023'!B7 -> 6 | AR8: ='2 mayıs-14 mayıs 2023'!B7 -> 9 | AS8: ='17 nisan-1 mayıs 2023'!B7 -> 4 | AT8: ='17 nisan-1 mayıs 2023'!B7 -> 4 | AU8: ='3-16 nisan 2023'!B7 -> 12 | AV8: ='20 Mart-2 nisan 2023'!B9 -> 10 | AW8: ='6 mart-19 mart 2023'!B9 -> 9 | AX8: ='20 şubat-5 mart 2023'!B7 -> 7 | AY8: ='23 ocak-17 şubat'!B7 -> 5 | AZ8: ='26 aralık-20 ocak'!B7 -> 18 | BB8: =SUM(AC8:AZ8) -> 180
A9: Yasemin | AG9: ='16-29 Ekim'!B8 -> 1 | AH9: ='2 Ekim-15 Ekim 2023 '!B8 -> 9 | AI9: ='18 Eylül-1 Ekim 2023'!B8 -> 3 | AJ9: ='28 Ağustos-17 Eylül 2023'!B8 -> 5 | AK9: ='14-27 Ağustos'!B8 -> 3 | AL9: ='31 Temmuz-13 Ağustos'!B8 -> 5 | AM9: ='17 Temmuz-30 Temmuz 2023'!B8 -> 5 | AN9: ='26 Haziran-16Temmuz 2023'!B8 -> 6 | AO9: ='12-25 Haziran 2023'!B8 | AP9: ='29 mayıs-11 Haziran 2023'!B8 | AQ9: ='15 mayıs-28 mayıs 2023'!B8 | AR9: ='2 mayıs-14 mayıs 2023'!B8 | AS9: ='17 nisan-1 mayıs 2023'!B8 | AT9: ='17 nisan-1 mayıs 2023'!B8 | AW9: ='6 mart-19 mart 2023'!B8 | AX9: ='20 şubat-5 mart 2023'!B8 | AY9: ='23 ocak-17 şubat'!B8 | AZ9: ='26 aralık-20 ocak'!B8 | BB9: =SUM(AC9:AZ9) -> 37
A10: Yılmaz | B10: ='9-22 Aralık 2024'!B8 -> 6 | C10: ='25 Kasım-8 Aralık 2024'!B8 -> 7 | D10: ='11_24 Kasım 2024'!B8 -> 7 | E10: ='30 Ekim-10 Kasım 2024'!B8 -> 18 | F10: ='14_29 Ekim 2024'!B8 -> 29 | G10: ='30 Eylül-13 Ekim 2024'!B8 -> 13 | H10: ='2-29 Eylül 2024'!B8 -> 19 | I10: ='19-30 Ağustos 2024'!B8 -> 9 | J10: ='5-18 Ağustos 2024'!B8 -> 6 | K10: ='22 Temmuz-4 Ağustos 2024'!B8 -> 11 | L10: ='8-21 Temmuz 2024'!B8 -> 4 | M10: ='17 Haziran-7 Temmuz 2024'!B8 -> 2 | N10: ='3-16 Haziran 2024'!B8 -> 6 | O10: ='20 Mayıs-2 Haziran 2024'!B8 -> 11 | P10: ='6-19 MAYIS'!B8 -> 17 | Q10: ='22 NİSAN-5 MAYIS'!B8 -> 10 | R10: ='1-21 Nisan 2024'!B8 -> 3 | S10: ='18-31 Mart 2024'!B8 -> 8 | T10: ='4-17 Mart 2024'!B8 -> 3 | U10: ='19 şubat-3 Mart 2024'!B8 -> 4 | V10: ='5 şubat-18 Şubat 2024'!B8 -> 6 | W10: ='22 Ocak-4 Şubat 2024'!B8 -> 9 | X10: ='8 Ocak-21 Ocak 2024'!B8 -> 7 | Y10: ='25Aralık 2023-7 Ocak 2024'!B8 -> 9 | AA10: =SUM(D10:Y10) -> 211 | AC10: ='11 Aralık-24Aralık 2023'!B8 -> 10 | AD10: ='27 Kasım-10 Aralık'!B8 -> 11 | AE10: ='13 Kasım-26 Kasım'!B8 -> 8 | AF10: ='30 Ekim-12 Kasım'!B8 -> 9 | AG10: ='16-29 Ekim'!B9 -> 4 | AH10: ='2 Ekim-15 Ekim 2023 '!B9 -> 9 | AI10: ='18 Eylül-1 Ekim 2023'!B9 -> 12 | AJ10: ='28 Ağustos-17 Eylül 2023'!B9 -> 13 | AK10: ='14-27 Ağustos'!B9 | AL10: ='31 Temmuz-13 Ağustos'!B9 -> 4 | AM10: ='17 Temmuz-30 Temmuz 2023'!B9 -> 7 | AN10: ='26 Haziran-16Temmuz 2023'!B9 | AO10: ='12-25 Haziran 2023'!B9 | AQ10: ='15 mayıs-28 mayıs 2023'!B9 | AR10: ='2 mayıs-14 mayıs 2023'!B9 | AS10: ='17 nisan-1 mayıs 2023'!B9 | AT10: ='17 nisan-1 mayıs 2023'!B9 | AX10: ='20 şubat-5 mart 2023'!B9 | AY10: ='23 ocak-17 şubat'!B9 | AZ10: ='26 aralık-20 ocak'!B9 | BB10: =SUM(AC10:AZ10) -> 87
A11: Devrim | B11: ='9-22 Aralık 2024'!B10 | D11: ='11_24 Kasım 2024'!B9 | AP11: ='29 mayıs-11 Haziran 2023'!B10 -> 2 | AQ11: ='15 mayıs-28 mayıs 2023'!B10 -> 4 | AR11: ='2 mayıs-14 mayıs 2023'!B10 -> 6 | AS11: ='17 nisan-1 mayıs 2023'!B10 -> 4 | AT11: ='17 nisan-1 mayıs 2023'!B10 -> 4 | AU11: ='3-16 nisan 2023'!B10 -> 8 | AV11: ='20 Mart-2 nisan 2023'!B10 -> 13 | AW11: ='6 mart-19 mart 2023'!B10 -> 12 | AX11: ='20 şubat-5 mart 2023'!B10 -> 12 | AY11: ='23 ocak-17 şubat'!B10 -> 16 | AZ11: ='26 aralık-20 ocak'!B10 -> 20 | BB11: =SUM(AC11:AZ11) -> 101
A12: Batuhan | B12: ='9-22 Aralık 2024'!B11 | AA12: =SUM(AA3:AA10) -> 1274 | AP12: ='29 mayıs-11 Haziran 2023'!B11 -> 1 | AQ12: ='15 mayıs-28 mayıs 2023'!B11 -> 10 | AR12: ='2 mayıs-14 mayıs 2023'!B11 -> 7 | AS12: ='17 nisan-1 mayıs 2023'!B11 -> 5 | AT12: ='17 nisan-1 mayıs 2023'!B11 -> 5 | AU12: ='3-16 nisan 2023'!B11 -> 13 | AV12: ='20 Mart-2 nisan 2023'!B11 -> 8 | AW12: ='6 mart-19 mart 2023'!B11 -> 5 | AX12: ='20 şubat-5 mart 2023'!B11 -> 4 | AY12: ='23 ocak-17 şubat'!B11 -> 9 | AZ12: ='26 aralık-20 ocak'!B11 -> 11 | BB12: =SUM(AC12:AZ12) -> 78
BB14: =SUM(BB3:BB12) -> 1589
E15: TOPLAM SCORE | AQ15: SP
A17: İslam | B17: ='9-22 Aralık 2024'!C2 -> 2.3 | C17: ='25 Kasım-8 Aralık 2024'!C2 -> 45.122 | D17: ='11_24 Kasım 2024'!C2 -> 41.82 | E17: ='30 Ekim-10 Kasım 2024'!C2 -> 34.825 | F17: ='14_29 Ekim 2024'!C2 -> 65.591 | G17: ='30 Eylül-13 Ekim 2024'!C2 -> 42.458 | H17: ='2-29 Eylül 2024'!C2 -> 86.81 | I17: ='19-30 Ağustos 2024'!C2 -> 76.6 | J17: ='5-18 Ağustos 2024'!C2 -> 71.055 | K17: ='22 Temmuz-4 Ağustos 2024'!C2 -> 72.52 | L17: ='8-21 Temmuz 2024'!C2 -> 60.25 | M17: ='17 Haziran-7 Temmuz 2024'!C2 -> 41 | N17: ='3-16 Haziran 2024'!C2 -> 60.692 | O17: ='20 Mayıs-2 Haziran 2024'!C2 -> 45 | P17: ='6-19 MAYIS'!C2 -> 114.596 | Q17: ='22 NİSAN-5 MAYIS'!C2 -> 35.375 | R17: ='1-21 Nisan 2024'!C2 -> 68.98 | S17: ='18-31 Mart 2024'!C2 -> 77.182 | T17: ='4-17 Mart 2024'!C2 -> 77.85 | U17: ='19 şubat-3 Mart 2024'!C2 -> 54.481 | V17: ='5 şubat-18 Şubat 2024'!C2 -> 55.5 | W17: ='22 Ocak-4 Şubat 2024'!C2 -> 76.789 | X17: ='8 Ocak-21 Ocak 2024'!C2 -> 73.098 | Y17: ='25Aralık 2023-7 Ocak 2024'!C2 -> 16 | AA17: =SUM(D17:Y17) -> 1348.472 | AC17: ='11 Aralık-24Aralık 2023'!C2 -> 44.92 | AD17: ='27 Kasım-10 Aralık'!C2 -> 56.546 | AE17: ='13 Kasım-26 Kasım'!C2 -> 52.453 | AF17: ='30 Ekim-12 Kasım'!C2 -> 43.428 | AG17: ='16-29 Ekim'!C2 -> 36.02 | AH17: ='2 Ekim-15 Ekim 2023 '!C2 -> 31.19 | AI17: ='18 Eylül-1 Ekim 2023'!C2 -> 87.599 | AJ17: ='28 Ağustos-17 Eylül 2023'!C2 -> 45.055 | AK17: ='14-27 Ağustos'!C2 -> 62.3 | AL17: ='31 Temmuz-13 Ağustos'!C2 -> 65.648 | AM17: ='17 Temmuz-30 Temmuz 2023'!C2 -> 63.009 | AN17: ='26 Haziran-16Temmuz 2023'!C2 -> 43.456 | AO17: ='12-25 Haziran 2023'!C2 -> 76.484 | AP17: ='29 mayıs-11 Haziran 2023'!C2 -> 39.39 | AQ17: ='15 mayıs-28 mayıs 2023'!C2 -> 6.5 | AR17: ='2 mayıs-14 mayıs 2023'!C2 -> 12.5 | AS17: ='17 nisan-1 mayıs 2023'!C2 -> 11 | AT17: ='17 nisan-1 mayıs 2023'!C2 -> 11 | AU17: ='3-16 nisan 2023'!C2 -> 5 | AV17: ='20 Mart-2 nisan 2023'!C2 -> 9.5 | AW17: ='6 mart-19 mart 2023'!C2 -> 18.5 | AX17: ='20 şubat-5 mart 2023'!C2 -> 11 | AY17: ='23 ocak-17 şubat'!C2 -> 45.5 | AZ17: ='26 aralık-20 ocak'!C2 -> 18.5 | BB17: =SUM(AC17:AP17) -> 747.498
A18: MuratSaç | B18: ='9-22 Aralık 2024'!C3 -> 61.54 | C18: ='25 Kasım-8 Aralık 2024'!C3 -> 66.348 | D18: ='11_24 Kasım 2024'!C3 -> 62.74 | E18: ='30 Ekim-10 Kasım 2024'!C3 -> 49.815 | F18: ='14_29 Ekim 2024'!C3 -> 46.76 | G18: ='30 Eylül-13 Ekim 2024'!C3 -> 63.58 | H18: ='2-29 Eylül 2024'!C3 -> 54.985 | I18: ='19-30 Ağustos 2024'!C3 -> 38.332 | J18: ='5-18 Ağustos 2024'!C3 -> 32.08 | K18: ='22 Temmuz-4 Ağustos 2024'!C3 -> 25 | L18: ='8-21 Temmuz 2024'!C3 -> 56.16 | M18: ='17 Haziran-7 Temmuz 2024'!C3 -> 60 | N18: ='3-16 Haziran 2024'!C3 -> 71.934 | O18: ='20 Mayıs-2 Haziran 2024'!C3 -> 17.6 | P18: ='6-19 MAYIS'!C3 -> 50.542 | Q18: ='22 NİSAN-5 MAYIS'!C3 -> 17.38 | R18: ='1-21 Nisan 2024'!C3 -> 34.538 | S18: ='18-31 Mart 2024'!C3 -> 40.848 | T18: ='4-17 Mart 2024'!C3 -> 65.13 | U18: ='19 şubat-3 Mart 2024'!C3 -> 20.838 | V18: ='5 şubat-18 Şubat 2024'!C3 -> 36.432 | W18: ='22 Ocak-4 Şubat 2024'!C3 -> 18.018 | X18: ='8 Ocak-21 Ocak 2024'!C3 -> 41 | Y18: ='25Aralık 2023-7 Ocak 2024'!C3 -> 40.48 | AA18: =SUM(D18:Y18) -> 944.192 | AC18: ='11 Aralık-24Aralık 2023'!C3 -> 54.104 | AD18: ='27 Kasım-10 Aralık'!C3 -> 38.388 | AE18: ='13 Kasım-26 Kasım'!C3 -> 74.574 | AF18: ='30 Ekim-12 Kasım'!C3 -> 41.988 | AG18: ='16-29 Ekim'!C3 -> 75.419 | AH18: ='2 Ekim-15 Ekim 2023 '!C3 -> 0 | AI18: ='18 Eylül-1 Ekim 2023'!C3 -> 73.764 | AJ18: ='28 Ağustos-17 Eylül 2023'!C3 -> 42.119 | AK18: ='14-27 Ağustos'!C3 -> 87.93 | AL18: ='31 Temmuz-13 Ağustos'!C3 -> 69.526 | AM18: ='17 Temmuz-30 Temmuz 2023'!C3 -> 26.456 | AN18: ='26 Haziran-16Temmuz 2023'!C3 -> 30.066 | AO18: ='12-25 Haziran 2023'!C3 -> 45.995 | AP18: ='29 mayıs-11 Haziran 2023'!C3 -> 39.023 | AQ18: ='15 mayıs-28 mayıs 2023'!C3 -> 7 | AR18: ='2 mayıs-14 mayıs 2023'!C3 -> 3 | AS18: ='17 nisan-1 mayıs 2023'!C3 -> 5.5 | AT18: ='17 nisan-1 mayıs 2023'!C3 -> 5.5 | AU18: ='3-16 nisan 2023'!C3 -> 15 | AV18: ='20 Mart-2 nisan 2023'!C3 -> 8.5 | AW18: ='6 mart-19 mart 2023'!C3 -> 4 | AX18: ='20 şubat-5 mart 2023'!C3 -> 14.5 | AY18: ='23 ocak-17 şubat'!C3 -> 26.5 | AZ18: ='26 aralık-20 ocak'!C3 -> 15 | BB18: =SUM(AC18:AP18) -> 699.352
A19: Emre | B19: ='9-22 Aralık 2024'!C4 -> 74.132 | C19: ='25 Kasım-8 Aralık 2024'!C4 -> 77.18 | D19: ='11_24 Kasım 2024'!C4 -> 81.52 | E19: ='30 Ekim-10 Kasım 2024'!C4 -> 55.76 | F19: ='14_29 Ekim 2024'!C4 -> 72.72 | G19: ='30 Eylül-13 Ekim 2024'!C4 -> 75.05 | H19: ='2-29 Eylül 2024'!C4 -> 114.704 | I19: ='19-30 Ağustos 2024'!C4 -> 69.57 | J19: ='5-18 Ağustos 2024'!C4 -> 89.588 | K19: ='22 Temmuz-4 Ağustos 2024'!C4 -> 69.565 | L19: ='8-21 Temmuz 2024'!C4 -> 58.785 | M19: ='17 Haziran-7 Temmuz 2024'!C4 -> 36.32 | N19: ='3-16 Haziran 2024'!C4 -> 70.86 | O19: ='20 Mayıs-2 Haziran 2024'!C4 -> 25.65 | P19: ='6-19 MAYIS'!C4 -> 82.44 | Q19: ='22 NİSAN-5 MAYIS'!C4 -> 50.37 | R19: ='1-21 Nisan 2024'!C4 -> 42.58 | S19: ='18-31 Mart 2024'!C4 -> 65.106 | T19: ='4-17 Mart 2024'!C4 -> 66.045 | U19: ='19 şubat-3 Mart 2024'!C4 -> 88.1 | V19: ='5 şubat-18 Şubat 2024'!C4 -> 64.395 | W19: ='22 Ocak-4 Şubat 2024'!C4 -> 80.978 | X19: ='8 Ocak-21 Ocak 2024'!C4 -> 80.674 | Y19: ='25Aralık 2023-7 Ocak 2024'!C4 -> 46.726 | AA19: =SUM(D19:Y19) -> 1487.506 | AC19: ='11 Aralık-24Aralık 2023'!C4 -> 74.208 | AD19: ='27 Kasım-10 Aralık'!C4 -> 79.885 | AE19: ='13 Kasım-26 Kasım'!C4 -> 92.408 | AF19: ='30 Ekim-12 Kasım'!C4 -> 80.861 | AG19: ='16-29 Ekim'!C4 -> 37.153 | AH19: ='2 Ekim-15 Ekim 2023 '!C4 -> 46.682 | AI19: ='18 Eylül-1 Ekim 2023'!C4 -> 75.291 | AJ19: ='28 Ağustos-17 Eylül 2023'!C4 -> 83.757 | AK19: ='14-27 Ağustos'!C4 -> 66.299 | AL19: ='31 Temmuz-13 Ağustos'!C4 -> 88.32 | AM19: ='17 Temmuz-30 Temmuz 2023'!C4 -> 86.3 | AN19: ='26 Haziran-16Temmuz 2023'!C4 -> 76.606 | AO19: ='12-25 Haziran 2023'!C4 -> 68.645 | AP19: ='29 mayıs-11 Haziran 2023'!C4 -> 67.96 | AQ19: ='15 mayıs-28 mayıs 2023'!C4 -> 11.5 | AR19: ='2 mayıs-14 mayıs 2023'!C4 -> 7 | AS19: ='17 nisan-1 mayıs 2023'!C4 -> 6.5 | AT19: ='17 nisan-1 mayıs 2023'!C4 -> 6.5 | AU19: ='3-16 nisan 2023'!C4 -> 12.5 | AV19: ='20 Mart-2 nisan 2023'!C4 -> 14 | AW19: ='6 mart-19 mart 2023'!C4 -> 7.5 | AX19: ='20 şubat-5 mart 2023'!C4 -> 11 | AY19: ='23 ocak-17 şubat'!C4 -> 24.5 | AZ19: ='26 aralık-20 ocak'!C4 -> 26 | BB19: =SUM(AC19:AP19) -> 1024.375
A20: Farhad | B20: ='9-22 Aralık 2024'!C5 -> 59.1 | C20: ='25 Kasım-8 Aralık 2024'!C5 -> 38.532 | D20: ='11_24 Kasım 2024'!C5 -> 63.932 | E20: ='30 Ekim-10 Kasım 2024'!C5 -> 46.12 | F20: ='14_29 Ekim 2024'!C5 -> 59.22 | G20: ='30 Eylül-13 Ekim 2024'!C5 -> 69.092 | H20: ='2-29 Eylül 2024'!C5 -> 96.779 | I20: ='19-30 Ağustos 2024'!C5 -> 32.2 | J20: ='5-18 Ağustos 2024'!C5 -> 49.07 | K20: ='22 Temmuz-4 Ağustos 2024'!C5 -> 58.08 | L20: ='8-21 Temmuz 2024'!C5 -> 83.824 | M20: ='17 Haziran-7 Temmuz 2024'!C5 -> 59.672 | N20: ='3-16 Haziran 2024'!C5 -> 80.872 | O20: ='20 Mayıs-2 Haziran 2024'!C5 -> 68.64 | P20: ='6-19 MAYIS'!C5 -> 51.82 | Q20: ='22 NİSAN-5 MAYIS'!C5 -> 53.37 | R20: ='1-21 Nisan 2024'!C5 -> 84.785 | S20: ='18-31 Mart 2024'!C5 -> 50.176 | T20: ='4-17 Mart 2024'!C5 -> 57.14 | U20: ='19 şubat-3 Mart 2024'!C5 -> 50.063 | V20: ='5 şubat-18 Şubat 2024'!C5 -> 51.925 | W20: ='22 Ocak-4 Şubat 2024'!C5 -> 9.56 | X20: ='8 Ocak-21 Ocak 2024'!C5 -> 51.839 | Y20: ='25Aralık 2023-7 Ocak 2024'!C5 -> 102.476 | AA20: =SUM(D20:Y20) -> 1330.655 | AC20: ='11 Aralık-24Aralık 2023'!C5 -> 52.668 | AD20: ='27 Kasım-10 Aralık'!C5 -> 62.32 | AE20: ='13 Kasım-26 Kasım'!C5 -> 86.02 | AF20: ='30 Ekim-12 Kasım'!C5 -> 87.44 | AG20: ='16-29 Ekim'!C5 -> 100.77 | AH20: ='2 Ekim-15 Ekim 2023 '!C5 -> 24.912 | AI20: ='18 Eylül-1 Ekim 2023'!C5 -> 83.492 | AJ20: ='28 Ağustos-17 Eylül 2023'!C5 -> 16.38 | AK20: ='14-27 Ağustos'!C5 -> 36.3 | AL20: ='31 Temmuz-13 Ağustos'!C5 -> 73.609 | AM20: ='17 Temmuz-30 Temmuz 2023'!C5 -> 56.43 | AN20: ='26 Haziran-16Temmuz 2023'!C5 -> 84.634 | AO20: ='12-25 Haziran 2023'!C5 -> 33.11 | AP20: ='29 mayıs-11 Haziran 2023'!C5 -> 101.718 | AQ20: ='15 mayıs-28 mayıs 2023'!C5 -> 11.5 | AR20: ='2 mayıs-14 mayıs 2023'!C5 -> 12.5 | AS20: ='17 nisan-1 mayıs 2023'!C5 -> 4 | AT20: ='17 nisan-1 mayıs 2023'!C5 -> 4 | AU20: ='3-16 nisan 2023'!C5 -> 5.5 | AV20: ='20 Mart-2 nisan 2023'!C5 -> 15.5 | AW20: ='6 mart-19 mart 2023'!C5 -> 8.5 | AX20: ='20 şubat-5 mart 2023'!C5 -> 21 | AY20: ='23 ocak-17 şubat'!C5 -> 16 | AZ20: ='26 aralık-20 ocak'!C5 -> 36 | BB20: =SUM(AC20:AP20) -> 899.803
A21: Ömer | B21: ='9-22 Aralık 2024'!C6 -> 40.66 | C21: ='25 Kasım-8 Aralık 2024'!C6 -> 55.865 | D21: ='11_24 Kasım 2024'!C6 -> 45.756 | E21: ='30 Ekim-10 Kasım 2024'!C6 -> 36.536 | F21: ='14_29 Ekim 2024'!C6 -> 61.67 | G21: ='30 Eylül-13 Ekim 2024'!C6 -> 49.984 | H21: ='2-29 Eylül 2024'!C6 -> 38.08 | I21: ='19-30 Ağustos 2024'!C6 -> 20.25 | J21: ='5-18 Ağustos 2024'!C6 -> 33.312 | K21: ='22 Temmuz-4 Ağustos 2024'!C6 -> 38.85 | L21: ='8-21 Temmuz 2024'!C6 -> 58.656 | M21: ='17 Haziran-7 Temmuz 2024'!C6 -> 45.744 | N21: ='3-16 Haziran 2024'!C6 -> 47.8 | O21: ='20 Mayıs-2 Haziran 2024'!C6 -> 75.325 | P21: ='6-19 MAYIS'!C6 -> 88.871 | Q21: ='22 NİSAN-5 MAYIS'!C6 -> 31.45 | R21: ='1-21 Nisan 2024'!C6 -> 53.11 | S21: ='18-31 Mart 2024'!C6 -> 30.894 | T21: ='4-17 Mart 2024'!C6 -> 55.328 | U21: ='19 şubat-3 Mart 2024'!C6 -> 40.825 | V21: ='5 şubat-18 Şubat 2024'!C6 -> 32.36 | W21: ='22 Ocak-4 Şubat 2024'!C6 -> 53.405 | X21: ='8 Ocak-21 Ocak 2024'!C6 -> 43.775 | Y21: ='25Aralık 2023-7 Ocak 2024'!C6 -> 55.125 | AA21: =SUM(D21:Y21) -> 1037.106 | AC21: ='11 Aralık-24Aralık 2023'!C6 -> 57.14 | AD21: ='27 Kasım-10 Aralık'!C6 -> 55.982 | AE21: ='13 Kasım-26 Kasım'!C6 -> 48.56 | AF21: ='30 Ekim-12 Kasım'!C6 -> 76.872 | AG21: ='16-29 Ekim'!C6 -> 31.32 | AH21: ='2 Ekim-15 Ekim 2023 '!C6 -> 21.78 | AI21: ='18 Eylül-1 Ekim 2023'!C6 -> 67.18 | AJ21: ='28 Ağustos-17 Eylül 2023'!C6 -> 65.888 | AK21: ='14-27 Ağustos'!C6 -> 45.286 | AL21: ='31 Temmuz-13 Ağustos'!C6 -> 31.11 | AM21: ='17 Temmuz-30 Temmuz 2023'!C6 -> 41.184 | AN21: ='26 Haziran-16Temmuz 2023'!C6 -> 56.598 | AO21: ='12-25 Haziran 2023'!C6 -> 55.675 | AP21: ='29 mayıs-11 Haziran 2023'!C6 -> 66.414 | AQ21: ='15 mayıs-28 mayıs 2023'!C6 -> 10 | AR21: ='2 mayıs-14 mayıs 2023'!C6 -> 5 | AS21: ='17 nisan-1 mayıs 2023'!C6 -> 5 | AT21: ='17 nisan-1 mayıs 2023'!C6 -> 5 | AU21: ='3-16 nisan 2023'!C6 -> 4 | AV21: ='20 Mart-2 nisan 2023'!C6 -> 15 | AW21: ='6 mart-19 mart 2023'!C6 -> 14 | AX21: ='20 şubat-5 mart 2023'!C6 -> 13.5 | AY21: ='23 ocak-17 şubat'!C6 -> 16.5 | AZ21: ='26 aralık-20 ocak'!C6 -> 21.5 | BB21: =SUM(AC21:AP21) -> 720.989
A22: Malik | B22: ='9-22 Aralık 2024'!C7 -> 93.97 | C22: ='25 Kasım-8 Aralık 2024'!C7 -> 47.652 | D22: ='11_24 Kasım 2024'!C7 -> 96.638 | E22: ='30 Ekim-10 Kasım 2024'!C7 -> 78.604 | F22: ='14_29 Ekim 2024'!C7 -> 101.78 | G22: ='30 Eylül-13 Ekim 2024'!C7 -> 186.76 | H22: ='2-29 Eylül 2024'!C7 -> 119.8 | I22: ='19-30 Ağustos 2024'!C7 -> 55.38 | J22: ='5-18 Ağustos 2024'!C7 -> 82.711 | K22: ='22 Temmuz-4 Ağustos 2024'!C7 -> 68.9 | L22: ='8-21 Temmuz 2024'!C7 -> 103.24 | M22: ='17 Haziran-7 Temmuz 2024'!C7 -> 104.01 | N22: ='3-16 Haziran 2024'!C7 -> 70.14 | O22: ='20 Mayıs-2 Haziran 2024'!C7 -> 22.176 | P22: ='6-19 MAYIS'!C7 -> 104.604 | Q22: ='22 NİSAN-5 MAYIS'!C7 -> 67.72 | R22: ='1-21 Nisan 2024'!C7 -> 84.818 | S22: ='18-31 Mart 2024'!C7 -> 119.67 | T22: ='4-17 Mart 2024'!C7 -> 108.592 | U22: ='19 şubat-3 Mart 2024'!C7 -> 75.04 | V22: ='5 şubat-18 Şubat 2024'!C7 -> 31.97 | W22: ='22 Ocak-4 Şubat 2024'!C7 -> 91.875 | X22: ='8 Ocak-21 Ocak 2024'!C7 -> 104.84 | Y22: ='25Aralık 2023-7 Ocak 2024'!C7 -> 66.44 | AA22: =SUM(D22:Y22) -> 1945.708 | AC22: ='11 Aralık-24Aralık 2023'!C7 -> 77.685 | AD22: ='27 Kasım-10 Aralık'!C7 -> 86.993 | AE22: ='13 Kasım-26 Kasım'!C7 -> 55.55 | AF22: ='30 Ekim-12 Kasım'!C7 -> 92.946 | AG22: ='16-29 Ekim'!C7 -> 92.328 | AH22: ='2 Ekim-15 Ekim 2023 '!C7 -> 97.908 | AI22: ='18 Eylül-1 Ekim 2023'!C7 -> 90.348 | AJ22: ='28 Ağustos-17 Eylül 2023'!C7 -> 78.695 | AK22: ='14-27 Ağustos'!C7 -> 71.49 | AL22: ='31 Temmuz-13 Ağustos'!C7 -> 75.167 | AM22: ='17 Temmuz-30 Temmuz 2023'!C7 -> 96.096 | AN22: ='26 Haziran-16Temmuz 2023'!C7 -> 96.352 | AO22: ='12-25 Haziran 2023'!C7 -> 63.73 | AP22: ='29 mayıs-11 Haziran 2023'!C7 -> 68.762 | AQ22: ='15 mayıs-28 mayıs 2023'!C7 -> 13 | AR22: ='2 mayıs-14 mayıs 2023'!C7 -> 13 | AS22: ='17 nisan-1 mayıs 2023'!C7 -> 10 | AT22: ='17 nisan-1 mayıs 2023'!C7 -> 10 | AU22: ='3-16 nisan 2023'!C7 -> 11.5 | AV22: ='20 Mart-2 nisan 2023'!C9 -> 11.5 | AW22: ='6 mart-19 mart 2023'!C9 -> 14.5 | AX22: ='20 şubat-5 mart 2023'!C7 -> 15 | AY22: ='23 ocak-17 şubat'!C7 -> 20 | AZ22: ='26 aralık-20 ocak'!C7 -> 42 | BB22: =SUM(AC22:AP22) -> 1144.05
A23: Yasemin | AA23: =SUM(D23:Y23) -> 0 | AG23: ='16-29 Ekim'!C8 -> 7.59 | AH23: ='2 Ekim-15 Ekim 2023 '!C8 -> 22.6 | AI23: ='18 Eylül-1 Ekim 2023'!C8 -> 11.03 | AJ23: ='28 Ağustos-17 Eylül 2023'!C8 -> 10.1 | AK23: ='14-27 Ağustos'!C8 -> 15.53 | AL23: ='31 Temmuz-13 Ağustos'!C8 -> 13.9 | AM23: ='17 Temmuz-30 Temmuz 2023'!C8 -> 13.3 | AN23: ='26 Haziran-16Temmuz 2023'!C8 -> 16.93 | AO23: ='12-25 Haziran 2023'!C8 | AP23: ='29 mayıs-11 Haziran 2023'!C8 | AQ23: ='15 mayıs-28 mayıs 2023'!C8 | AR23: ='2 mayıs-14 mayıs 2023'!C8 | AS23: ='17 nisan-1 mayıs 2023'!C8 | AT23: ='17 nisan-1 mayıs 2023'!C8 | AW23: ='6 mart-19 mart 2023'!C8 | AX23: ='20 şubat-5 mart 2023'!C8 | AY23: ='23 ocak-17 şubat'!C8 | AZ23: ='26 aralık-20 ocak'!C8 | BB23: =SUM(AC23:AP23) -> 110.98
A24: Yılmaz | B24: ='9-22 Aralık 2024'!C8 -> 42 | C24: ='25 Kasım-8 Aralık 2024'!C8 -> 43.41 | D24: ='11_24 Kasım 2024'!C8 -> 45.63 | E24: ='30 Ekim-10 Kasım 2024'!C8 -> 44.244 | F24: ='14_29 Ekim 2024'!C8 -> 51.05 | G24: ='30 Eylül-13 Ekim 2024'!C8 -> 44.44 | H24: ='2-29 Eylül 2024'!C8 -> 117.19 | I24: ='19-30 Ağustos 2024'!C8 -> 44.222 | J24: ='5-18 Ağustos 2024'!C8 -> 73.52 | K24: ='22 Temmuz-4 Ağustos 2024'!C8 -> 64.22 | L24: ='8-21 Temmuz 2024'!C8 -> 39.91 | M24: ='17 Haziran-7 Temmuz 2024'!C8 -> 45 | N24: ='3-16 Haziran 2024'!C8 -> 62.77 | O24: ='20 Mayıs-2 Haziran 2024'!C8 -> 49.67 | P24: ='6-19 MAYIS'!C8 -> 69.93 | Q24: ='22 NİSAN-5 MAYIS'!C8 -> 56.278 | R24: ='1-21 Nisan 2024'!C8 -> 22.66 | S24: ='18-31 Mart 2024'!C8 -> 57.195 | T24: ='4-17 Mart 2024'!C8 -> 65.02 | U24: ='19 şubat-3 Mart 2024'!C8 -> 75.872 | V24: ='5 şubat-18 Şubat 2024'!C8 -> 29.872 | W24: ='22 Ocak-4 Şubat 2024'!C8 -> 34.009 | X24: ='8 Ocak-21 Ocak 2024'!C8 -> 19.602 | Y24: ='25Aralık 2023-7 Ocak 2024'!C8 -> 41.58 | AA24: =SUM(D24:Y24) -> 1153.884 | AC24: ='11 Aralık-24Aralık 2023'!C8 -> 41.458 | AD24: ='27 Kasım-10 Aralık'!C8 -> 48.62 | AE24: ='13 Kasım-26 Kasım'!C8 -> 30.56 | AF24: ='30 Ekim-12 Kasım'!C8 -> 72.02 | AG24: ='16-29 Ekim'!C9 -> 19.095 | AH24: ='2 Ekim-15 Ekim 2023 '!C9 -> 80.776 | AI24: ='18 Eylül-1 Ekim 2023'!C9 -> 65.278 | AJ24: ='28 Ağustos-17 Eylül 2023'!C9 -> 61.51 | AK24: ='14-27 Ağustos'!C9 | AL24: ='31 Temmuz-13 Ağustos'!C9 -> 131.473 | AM24: ='17 Temmuz-30 Temmuz 2023'!C9 -> 44.502 | AN24: ='26 Haziran-16Temmuz 2023'!C9 | AO24: ='12-25 Haziran 2023'!C9 | AP24: ='29 mayıs-11 Haziran 2023'!C9 | AQ24: ='15 mayıs-28 mayıs 2023'!C9 | AR24: ='2 mayıs-14 mayıs 2023'!C9 | AS24: ='17 nisan-1 mayıs 2023'!C9 | AT24: ='17 nisan-1 mayıs 2023'!C9 | AX24: ='20 şubat-5 mart 2023'!C9 | AY24: ='23 ocak-17 şubat'!C9 | AZ24: ='26 aralık-20 ocak'!C9 | BB24: =SUM(AC24:AP24) -> 595.292
A25: Devrim | C25: ='25 Kasım-8 Aralık 2024'!C10 | AA25: =SUM(D25:Y25) -> 0 | AP25: ='29 mayıs-11 Haziran 2023'!C10 -> 59.4 | AQ25: ='15 mayıs-28 mayıs 2023'!C10 -> 2 | AR25: ='2 mayıs-14 mayıs 2023'!C10 -> 5 | AS25: ='17 nisan-1 mayıs 2023'!C10 -> 6 | AT25: ='17 nisan-1 mayıs 2023'!C10 -> 6 | AU25: ='3-16 nisan 2023'!C10 -> 8.5 | AV25: ='20 Mart-2 nisan 2023'!C10 -> 11.5 | AW25: ='6 mart-19 mart 2023'!C10 -> 13.5 | AX25: ='20 şubat-5 mart 2023'!C10 -> 10 | AY25: ='23 ocak-17 şubat'!C10 -> 18.5 | AZ25: ='26 aralık-20 ocak'!C10 -> 18 | BB25: 59.4
A26: Batuhan | C26: ='25 Kasım-8 Aralık 2024'!C11 | AP26: ='29 mayıs-11 Haziran 2023'!C11 -> 40 | AQ26: ='15 mayıs-28 mayıs 2023'!C11 -> 9 | AR26: ='2 mayıs-14 mayıs 2023'!C11 -> 6 | AS26: ='17 nisan-1 mayıs 2023'!C11 -> 5.5 | AT26: ='17 nisan-1 mayıs 2023'!C11 -> 5.5 | AU26: ='3-16 nisan 2023'!C11 -> 10.5 | AV26: ='20 Mart-2 nisan 2023'!C11 -> 13.5 | AW26: ='6 mart-19 mart 2023'!C11 -> 4 | AX26: ='20 şubat-5 mart 2023'!C11 -> 10.5 | AY26: ='23 ocak-17 şubat'!C11 -> 10 | AZ26: ='26 aralık-20 ocak'!C11 -> 19 | BB26: 40
E27: BEKLENEN SCORE | AA27: =SUM(AA17:AA25) -> 9247.523 | BB27: =SUM(BB17:BB26) -> 6041.739
G29: 45565 | J29: 45509 | L29: 45481 | O29: 20 MAYIS | U29: 45341 | AQ29: SP
A30: İslam | B30: ='9-22 Aralık 2024'!D2 -> 50 | C30: ='25 Kasım-8 Aralık 2024'!D2 -> 90 | D30: ='11_24 Kasım 2024'!D2 -> 90 | E30: ='30 Ekim-10 Kasım 2024'!D2 -> 80 | F30: ='14_29 Ekim 2024'!D2 -> 100 | G30: ='30 Eylül-13 Ekim 2024'!D2 -> 100 | H30: ='2-29 Eylül 2024'!D2 -> 150 | I30: ='19-30 Ağustos 2024'!D2 -> 90 | J30: ='5-18 Ağustos 2024'!D2 -> 100 | K30: ='22 Temmuz-4 Ağustos 2024'!D2 -> 100 | L30: ='8-21 Temmuz 2024'!D2 -> 80 | M30: ='17 Haziran-7 Temmuz 2024'!D2 -> 100 | N30: ='3-16 Haziran 2024'!D2 -> 100 | O30: ='20 Mayıs-2 Haziran 2024'!D2 -> 100 | P30: ='6-19 MAYIS'!D2 -> 95 | Q30: ='22 NİSAN-5 MAYIS'!D2 -> 75 | R30: ='1-21 Nisan 2024'!D2 -> 115 | S30: ='18-31 Mart 2024'!D2 -> 100 | T30: ='4-17 Mart 2024'!D2 -> 100 | U30: ='19 şubat-3 Mart 2024'!D2 -> 100 | V30: ='5 şubat-18 Şubat 2024'!D2 -> 100 | W30: ='22 Ocak-4 Şubat 2024'!D2 -> 100 | X30: ='8 Ocak-21 Ocak 2024'!D2 -> 100 | Y30: ='25Aralık 2023-7 Ocak 2024'!D2 -> 40 | AA30: =SUM(D30:Y30) -> 2115 | AC30: ='11 Aralık-24Aralık 2023'!D2 -> 100 | AD30: ='27 Kasım-10 Aralık'!D2 -> 80 | AE30: ='13 Kasım-26 Kasım'!D2 -> 100 | AF30: ='30 Ekim-12 Kasım'!D2 -> 100 | AG30: ='16-29 Ekim'!D2 -> 100 | AH30: ='2 Ekim-15 Ekim 2023 '!D2 -> 100 | AI30: ='18 Eylül-1 Ekim 2023'!D2 -> 90 | AJ30: ='28 Ağustos-17 Eylül 2023'!D2 -> 120 | AK30: ='14-27 Ağustos'!D2 -> 80 | AL30: ='31 Temmuz-13 Ağustos'!D2 -> 100 | AM30: ='17 Temmuz-30 Temmuz 2023'!D2 -> 100 | AN30: ='26 Haziran-16Temmuz 2023'!D2 -> 90 | AO30: ='12-25 Haziran 2023'!D2 -> 100 | AP30: ='29 mayıs-11 Haziran 2023'!D2 -> 100 | AQ30: ='15 mayıs-28 mayıs 2023'!D2 -> 18 | AR30: ='2 mayıs-14 mayıs 2023'!D2 -> 18 | AS30: ='17 nisan-1 mayıs 2023'!D2 -> 16 | AT30: ='17 nisan-1 mayıs 2023'!D2 -> 16 | AU30: ='3-16 nisan 2023'!D2 -> 20 | AV30: ='20 Mart-2 nisan 2023'!D2 -> 20 | AW30: ='6 mart-19 mart 2023'!D2 -> 20 | AX30: ='20 şubat-5 mart 2023'!D2 -> 16 | AY30: ='23 ocak-17 şubat'!D2 -> 36 | AZ30: ='26 aralık-20 ocak'!D2 -> 40 | BB30: =SUM(AC30:AP30) -> 1360
A31: MuratSaç | B31: ='9-22 Aralık 2024'!D3 -> 75 | C31: ='25 Kasım-8 Aralık 2024'!D3 -> 75 | D31: ='11_24 Kasım 2024'!D3 -> 75 | E31: ='30 Ekim-10 Kasım 2024'!D3 -> 60 | F31: ='14_29 Ekim 2024'!D3 -> 75 | G31: ='30 Eylül-13 Ekim 2024'!D3 -> 75 | H31: ='2-29 Eylül 2024'!D3 -> 105 | I31: ='19-30 Ağustos 2024'!D3 -> 37.5 | J31: ='5-18 Ağustos 2024'!D3 -> 75 | K31: ='22 Temmuz-4 Ağustos 2024'!D3 -> 37.5 | L31: ='8-21 Temmuz 2024'!D3 -> 67.5 | M31: ='17 Haziran-7 Temmuz 2024'!D3 -> 67.5 | N31: ='3-16 Haziran 2024'!D3 -> 75 | O31: ='20 Mayıs-2 Haziran 2024'!D3 -> 75 | P31: ='6-19 MAYIS'!D3 -> 75 | Q31: ='22 NİSAN-5 MAYIS'!D3 -> 45 | R31: ='1-21 Nisan 2024'!D3 -> 86.25 | S31: ='18-31 Mart 2024'!D3 -> 75 | T31: ='4-17 Mart 2024'!D3 -> 60 | U31: ='19 şubat-3 Mart 2024'!D3 -> 67.5 | V31: ='5 şubat-18 Şubat 2024'!D3 -> 52.5 | W31: ='22 Ocak-4 Şubat 2024'!D3 -> 52.5 | X31: ='8 Ocak-21 Ocak 2024'!D3 -> 75 | Y31: ='25Aralık 2023-7 Ocak 2024'!D3 -> 67.5 | AA31: =SUM(D31:Y31) -> 1481.25 | AC31: ='11 Aralık-24Aralık 2023'!D3 -> 75 | AD31: ='27 Kasım-10 Aralık'!D3 -> 63.75 | AE31: ='13 Kasım-26 Kasım'!D3 -> 75 | AF31: ='30 Ekim-12 Kasım'!D3 -> 75 | AG31: ='16-29 Ekim'!D3 -> 75 | AH31: ='2 Ekim-15 Ekim 2023 '!D3 -> 45 | AI31: ='18 Eylül-1 Ekim 2023'!D3 -> 75 | AJ31: ='28 Ağustos-17 Eylül 2023'!D3 -> 60 | AK31: ='14-27 Ağustos'!D3 -> 60 | AL31: ='31 Temmuz-13 Ağustos'!D3 -> 75 | AM31: ='17 Temmuz-30 Temmuz 2023'!D3 -> 50 | AN31: ='26 Haziran-16Temmuz 2023'!D3 -> 37.5 | AO31: ='12-25 Haziran 2023'!D3 -> 75 | AP31: ='29 mayıs-11 Haziran 2023'!D3 -> 75 | AQ31: ='15 mayıs-28 mayıs 2023'!D3 -> 13.5 | AR31: ='2 mayıs-14 mayıs 2023'!D3 -> 13.5 | AS31: ='17 nisan-1 mayıs 2023'!D3 -> 12 | AT31: ='17 nisan-1 mayıs 2023'!D3 -> 12 | AU31: ='3-16 nisan 2023'!D3 -> 15 | AV31: ='20 Mart-2 nisan 2023'!D3 -> 15 | AW31: ='6 mart-19 mart 2023'!D3 -> 15 | AX31: ='20 şubat-5 mart 2023'!D3 -> 15 | AY31: ='23 ocak-17 şubat'!D3 -> 30 | AZ31: ='26 aralık-20 ocak'!D3 -> 30 | BB31: =SUM(AC31:AP31) -> 916.25
A32: Emre | B32: ='9-22 Aralık 2024'!D4 -> 100 | C32: ='25 Kasım-8 Aralık 2024'!D4 -> 100 | D32: ='11_24 Kasım 2024'!D4 -> 100 | E32: ='30 Ekim-10 Kasım 2024'!D4 -> 80 | F32: ='14_29 Ekim 2024'!D4 -> 100 | G32: ='30 Eylül-13 Ekim 2024'!D4 -> 100 | H32: ='2-29 Eylül 2024'!D4 -> 150 | I32: ='19-30 Ağustos 2024'!D4 -> 80 | J32: ='5-18 Ağustos 2024'!D4 -> 85 | K32: ='22 Temmuz-4 Ağustos 2024'!D4 -> 100 | L32: ='8-21 Temmuz 2024'!D4 -> 90 | M32: ='17 Haziran-7 Temmuz 2024'!D4 -> 70 | N32: ='3-16 Haziran 2024'!D4 -> 100 | O32: ='20 Mayıs-2 Haziran 2024'!D4 -> 100 | P32: ='6-19 MAYIS'!D4 -> 100 | Q32: ='22 NİSAN-5 MAYIS'!D4 -> 80 | R32: ='1-21 Nisan 2024'!D4 -> 60 | S32: ='18-31 Mart 2024'!D4 -> 100 | T32: ='4-17 Mart 2024'!D4 -> 100 | U32: ='19 şubat-3 Mart 2024'!D4 -> 100 | V32: ='5 şubat-18 Şubat 2024'!D4 -> 95 | W32: ='22 Ocak-4 Şubat 2024'!D4 -> 95 | X32: ='8 Ocak-21 Ocak 2024'!D4 -> 100 | Y32: ='25Aralık 2023-7 Ocak 2024'!D4 -> 80 | AA32: =SUM(D32:Y32) -> 2065 | AC32: ='11 Aralık-24Aralık 2023'!D4 -> 100 | AD32: ='27 Kasım-10 Aralık'!D4 -> 100 | AE32: ='13 Kasım-26 Kasım'!D4 -> 100 | AF32: ='30 Ekim-12 Kasım'!D4 -> 90 | AG32: ='16-29 Ekim'!D4 -> 50 | AH32: ='2 Ekim-15 Ekim 2023 '!D4 -> 50 | AI32: ='18 Eylül-1 Ekim 2023'!D4 -> 100 | AJ32: ='28 Ağustos-17 Eylül 2023'!D4 -> 110 | AK32: ='14-27 Ağustos'!D4 -> 80 | AL32: ='31 Temmuz-13 Ağustos'!D4 -> 100 | AM32: ='17 Temmuz-30 Temmuz 2023'!D4 -> 100 | AN32: ='26 Haziran-16Temmuz 2023'!D4 -> 100 | AO32: ='12-25 Haziran 2023'!D4 -> 100 | AP32: ='29 mayıs-11 Haziran 2023'!D4 -> 100 | AQ32: ='15 mayıs-28 mayıs 2023'!D4 -> 18 | AR32: ='2 mayıs-14 mayıs 2023'!D4 -> 10 | AS32: ='17 nisan-1 mayıs 2023'!D4 -> 16 | AT32: ='17 nisan-1 mayıs 2023'!D4 -> 16 | AU32: ='3-16 nisan 2023'!D4 -> 20 | AV32: ='20 Mart-2 nisan 2023'!D4 -> 20 | AW32: ='6 mart-19 mart 2023'!D4 -> 16 | AX32: ='20 şubat-5 mart 2023'!D4 -> 20 | AY32: ='23 ocak-17 şubat'!D4 -> 40 | AZ32: ='26 aralık-20 ocak'!D4 -> 30 | BB32: =SUM(AC32:AP32) -> 1280
A33: Farhad | B33: ='9-22 Aralık 2024'!D5 -> 75 | C33: ='25 Kasım-8 Aralık 2024'!D5 -> 75 | D33: ='11_24 Kasım 2024'!D5 -> 75 | E33: ='30 Ekim-10 Kasım 2024'!D5 -> 56.25 | F33: ='14_29 Ekim 2024'!D5 -> 75 | G33: ='30 Eylül-13 Ekim 2024'!D5 -> 75 | H33: ='2-29 Eylül 2024'!D5 -> 105 | I33: ='19-30 Ağustos 2024'!D5 -> 30 | J33: ='5-18 Ağustos 2024'!D5 -> 37.5 | K33: ='22 Temmuz-4 Ağustos 2024'!D5 -> 75 | L33: ='8-21 Temmuz 2024'!D5 -> 67.5 | M33: ='17 Haziran-7 Temmuz 2024'!D5 -> 90 | N33: ='3-16 Haziran 2024'!D5 -> 75 | O33: ='20 Mayıs-2 Haziran 2024'!D5 -> 75 | P33: ='6-19 MAYIS'!D5 -> 75 | Q33: ='22 NİSAN-5 MAYIS'!D5 -> 60 | R33: ='1-21 Nisan 2024'!D5 -> 71.25 | S33: ='18-31 Mart 2024'!D5 -> 60 | T33: ='4-17 Mart 2024'!D5 -> 75 | U33: ='19 şubat-3 Mart 2024'!D5 -> 75 | V33: ='5 şubat-18 Şubat 2024'!D5 -> 37.5 | W33: ='22 Ocak-4 Şubat 2024'!D5 -> 37.5 | X33: ='8 Ocak-21 Ocak 2024'!D5 -> 60 | Y33: ='25Aralık 2023-7 Ocak 2024'!D5 -> 67.5 | AA33: =SUM(D33:Y33) -> 1455 | AC33: ='11 Aralık-24Aralık 2023'!D5 -> 71.25 | AD33: ='27 Kasım-10 Aralık'!D5 -> 75 | AE33: ='13 Kasım-26 Kasım'!D5 -> 67.5 | AF33: ='30 Ekim-12 Kasım'!D5 -> 75 | AG33: ='16-29 Ekim'!D5 -> 75 | AH33: ='2 Ekim-15 Ekim 2023 '!D5 -> 75 | AI33: ='18 Eylül-1 Ekim 2023'!D5 -> 60 | AJ33: ='28 Ağustos-17 Eylül 2023'!D5 -> 37.5 | AK33: ='14-27 Ağustos'!D5 -> 60 | AL33: ='31 Temmuz-13 Ağustos'!D5 -> 75 | AM33: ='17 Temmuz-30 Temmuz 2023'!D5 -> 90 | AN33: ='26 Haziran-16Temmuz 2023'!D5 -> 67.5 | AO33: ='12-25 Haziran 2023'!D5 -> 75 | AP33: ='29 mayıs-11 Haziran 2023'!D5 -> 75 | AQ33: ='15 mayıs-28 mayıs 2023'!D5 -> 14.4 | AR33: ='2 mayıs-14 mayıs 2023'!D5 -> 13.5 | AS33: ='17 nisan-1 mayıs 2023'!D5 -> 10.5 | AT33: ='17 nisan-1 mayıs 2023'!D5 -> 10.5 | AU33: ='3-16 nisan 2023'!D5 -> 7.5 | AV33: ='20 Mart-2 nisan 2023'!D5 -> 7.5 | AW33: ='6 mart-19 mart 2023'!D5 -> 15 | AX33: ='20 şubat-5 mart 2023'!D5 -> 12 | AY33: ='23 ocak-17 şubat'!D5 -> 30 | AZ33: ='26 aralık-20 ocak'!D5 -> 30 | BB33: =SUM(AC33:AP33) -> 978.75
A34: Ömer | B34: ='9-22 Aralık 2024'!D6 -> 100 | C34: ='25 Kasım-8 Aralık 2024'!D6 -> 90 | D34: ='11_24 Kasım 2024'!D6 -> 100 | E34: ='30 Ekim-10 Kasım 2024'!D6 -> 80 | F34: ='14_29 Ekim 2024'!D6 -> 100 | G34: ='30 Eylül-13 Ekim 2024'!D6 -> 100 | H34: ='2-29 Eylül 2024'!D6 -> 150 | I34: ='19-30 Ağustos 2024'!D6 -> 40 | J34: ='5-18 Ağustos 2024'!D6 -> 100 | K34: ='22 Temmuz-4 Ağustos 2024'!D6 -> 100 | L34: ='8-21 Temmuz 2024'!D6 -> 90 | M34: ='17 Haziran-7 Temmuz 2024'!D6 -> 120 | N34: ='3-16 Haziran 2024'!D6 -> 100 | O34: ='20 Mayıs-2 Haziran 2024'!D6 -> 100 | P34: ='6-19 MAYIS'!D6 -> 100 | Q34: ='22 NİSAN-5 MAYIS'!D6 -> 65 | R34: ='1-21 Nisan 2024'!D6 -> 105 | S34: ='18-31 Mart 2024'!D6 -> 50 | T34: ='4-17 Mart 2024'!D6 -> 100 | U34: ='19 şubat-3 Mart 2024'!D6 -> 100 | V34: ='5 şubat-18 Şubat 2024'!D6 -> 100 | W34: ='22 Ocak-4 Şubat 2024'!D6 -> 100 | X34: ='8 Ocak-21 Ocak 2024'!D6 -> 100 | Y34: ='25Aralık 2023-7 Ocak 2024'!D6 -> 90 | AA34: =SUM(D34:Y34) -> 2090 | AC34: ='11 Aralık-24Aralık 2023'!D6 -> 100 | AD34: ='27 Kasım-10 Aralık'!D6 -> 90 | AE34: ='13 Kasım-26 Kasım'!D6 -> 100 | AF34: ='30 Ekim-12 Kasım'!D6 -> 100 | AG34: ='16-29 Ekim'!D6 -> 50 | AH34: ='2 Ekim-15 Ekim 2023 '!D6 -> 70 | AI34: ='18 Eylül-1 Ekim 2023'!D6 -> 100 | AJ34: ='28 Ağustos-17 Eylül 2023'!D6 -> 120 | AK34: ='14-27 Ağustos'!D6 -> 64 | AL34: ='31 Temmuz-13 Ağustos'!D6 -> 80 | AM34: ='17 Temmuz-30 Temmuz 2023'!D6 -> 80 | AN34: ='26 Haziran-16Temmuz 2023'!D6 -> 80 | AO34: ='12-25 Haziran 2023'!D6 -> 80 | AP34: ='29 mayıs-11 Haziran 2023'!D6 -> 80 | AQ34: ='15 mayıs-28 mayıs 2023'!D6 -> 14.4 | AR34: ='2 mayıs-14 mayıs 2023'!D6 -> 14.4 | AS34: ='17 nisan-1 mayıs 2023'!D6 -> 12.8 | AT34: ='17 nisan-1 mayıs 2023'!D6 -> 12.8 | AU34: ='3-16 nisan 2023'!D6 -> 16 | AV34: ='20 Mart-2 nisan 2023'!D6 -> 12 | AW34: ='6 mart-19 mart 2023'!D6 -> 12 | AX34: ='20 şubat-5 mart 2023'!D6 -> 12 | AY34: ='23 ocak-17 şubat'!D6 -> 24 | AZ34: ='26 aralık-20 ocak'!D6 -> 28 | BB34: =SUM(AC34:AP34) -> 1194
A35: Malik | B35: ='9-22 Aralık 2024'!D7 -> 100 | C35: ='25 Kasım-8 Aralık 2024'!D7 -> 100 | D35: ='11_24 Kasım 2024'!D7 -> 100 | E35: ='30 Ekim-10 Kasım 2024'!D7 -> 75 | F35: ='14_29 Ekim 2024'!D7 -> 100 | G35: ='30 Eylül-13 Ekim 2024'!D7 -> 100 | H35: ='2-29 Eylül 2024'!D7 -> 150 | I35: ='19-30 Ağustos 2024'!D7 -> 80 | J35: ='5-18 Ağustos 2024'!D7 -> 100 | K35: ='22 Temmuz-4 Ağustos 2024'!D7 -> 100 | L35: ='8-21 Temmuz 2024'!D7 -> 90 | M35: ='17 Haziran-7 Temmuz 2024'!D7 -> 120 | N35: ='3-16 Haziran 2024'!D7 -> 100 | O35: ='20 Mayıs-2 Haziran 2024'!D7 -> 50 | P35: ='6-19 MAYIS'!D7 -> 100 | Q35: ='22 NİSAN-5 MAYIS'!D7 -> 80 | R35: ='1-21 Nisan 2024'!D7 -> 115 | S35: ='18-31 Mart 2024'!D7 -> 100 | T35: ='4-17 Mart 2024'!D7 -> 100 | U35: ='19 şubat-3 Mart 2024'!D7 -> 100 | V35: ='5 şubat-18 Şubat 2024'!D7 -> 85 | W35: ='22 Ocak-4 Şubat 2024'!D7 -> 85 | X35: ='8 Ocak-21 Ocak 2024'!D7 -> 100 | Y35: ='25Aralık 2023-7 Ocak 2024'!D7 -> 80 | AA35: =SUM(D35:Y35) -> 2110 | AC35: ='11 Aralık-24Aralık 2023'!D7 -> 100 | AD35: ='27 Kasım-10 Aralık'!D7 -> 90 | AE35: ='13 Kasım-26 Kasım'!D7 -> 50 | AF35: ='30 Ekim-12 Kasım'!D7 -> 100 | AG35: ='16-29 Ekim'!D7 -> 90 | AH35: ='2 Ekim-15 Ekim 2023 '!D7 -> 100 | AI35: ='18 Eylül-1 Ekim 2023'!D7 -> 100 | AJ35: ='28 Ağustos-17 Eylül 2023'!D7 -> 110 | AK35: ='14-27 Ağustos'!D7 -> 64 | AL35: ='31 Temmuz-13 Ağustos'!D7 -> 80 | AM35: ='17 Temmuz-30 Temmuz 2023'!D7 -> 80 | AN35: ='26 Haziran-16Temmuz 2023'!D7 -> 92 | AO35: ='12-25 Haziran 2023'!D7 -> 80 | AP35: ='29 mayıs-11 Haziran 2023'!D7 -> 80 | AQ35: ='15 mayıs-28 mayıs 2023'!D7 -> 14.4 | AR35: ='2 mayıs-14 mayıs 2023'!D7 -> 14.4 | AS35: ='17 nisan-1 mayıs 2023'!D7 -> 11.2 | AT35: ='17 nisan-1 mayıs 2023'!D7 -> 11.2 | AU35: ='3-16 nisan 2023'!D7 -> 16 | AV35: ='20 Mart-2 nisan 2023'!D9 -> 16 | AW35: ='6 mart-19 mart 2023'!D9 -> 16 | AX35: ='20 şubat-5 mart 2023'!D7 -> 15 | AY35: ='23 ocak-17 şubat'!D7 -> 26.2 | AZ35: ='26 aralık-20 ocak'!D7 -> 32 | BB35: =SUM(AC35:AP35) -> 1216
A36: Yasemin | AG36: ='16-29 Ekim'!D8 -> 42.5 | AH36: ='2 Ekim-15 Ekim 2023 '!D8 -> 50 | AI36: ='18 Eylül-1 Ekim 2023'!D8 -> 50 | AJ36: ='28 Ağustos-17 Eylül 2023'!D8 -> 60 | AK36: ='14-27 Ağustos'!D8 -> 40 | AL36: ='31 Temmuz-13 Ağustos'!D8 -> 50 | AM36: ='17 Temmuz-30 Temmuz 2023'!D8 -> 40 | AN36: ='26 Haziran-16Temmuz 2023'!D8 -> 50 | AO36: ='12-25 Haziran 2023'!D8 | AP36: ='29 mayıs-11 Haziran 2023'!D8 | AQ36: ='15 mayıs-28 mayıs 2023'!D8 | AR36: ='2 mayıs-14 mayıs 2023'!D8 | AS36: ='17 nisan-1 mayıs 2023'!D8 | AT36: ='17 nisan-1 mayıs 2023'!D8 | AU36: ='3-16 nisan 2023'!D8 | AV36: ='20 Mart-2 nisan 2023'!D8 | AW36: ='6 mart-19 mart 2023'!D8 | AX36: ='20 şubat-5 mart 2023'!D8 | AY36: ='23 ocak-17 şubat'!D8 | AZ36: ='26 aralık-20 ocak'!D8 | BB36: =SUM(AC36:AP36) -> 382.5
